<?xml version="1.0" ?>
<!-- =================================================================================== -->
<!-- |    This document was autogenerated by xacro from techtory_demo_description.urdf.xacro | -->
<!-- |    EDITING THIS FILE BY HAND IS NOT RECOMMENDED                                 | -->
<!-- =================================================================================== -->
<robot name="techtory_demo_description">
  <!--
    Base Denso robot xacro macro.

    NOTE this is NOT a URDF. It cannot directly be loaded by consumers
    expecting a flattened '.urdf' file. See the top-level '.xacro' for that
    (but note that .xacro must still be processed by the xacro command).

    This file models the base kinematic chain of a Denso robot.

    Author DENSO WAVE INCORPORATED
  -->
  <!-- <link name="world"/>
		<joint name="$(arg namespace)joint_w" type="fixed">
			<parent link="world"/>
			<child link="$(arg namespace)base_link"/>
		</joint> -->
  <link name="cobotta_pro_base_link">
    <visual>
      <origin rpy="0 0 0" xyz="0 0 0"/>
      <geometry>
        <mesh filename="package://denso_robot_descriptions/robots/cvrb0609/meshes/base_link.dae" scale="1 1 1"/>
      </geometry>
    </visual>
    <collision>
      <origin rpy="0 0 0" xyz="0 0 0"/>
      <geometry>
        <mesh filename="package://denso_robot_descriptions/robots/cvrb0609/meshes/base_link.dae" scale="1 1 1"/>
      </geometry>
    </collision>
    <inertial>
      <mass value="1"/>
      <origin rpy="0.000000 0.000000 0.000000" xyz="0.000000 0.000000 0.000000"/>
      <inertia ixx="1" ixy="0" ixz="0" iyy="1" iyz="0" izz="1"/>
    </inertial>
  </link>
  <link name="cobotta_pro_J1">
    <visual>
      <origin rpy="0 0 0" xyz="0 0 0"/>
      <geometry>
        <mesh filename="package://denso_robot_descriptions/robots/cvrb0609/meshes/J1.dae" scale="1 1 1"/>
      </geometry>
    </visual>
    <collision>
      <origin rpy="0 0 0" xyz="0 0 0"/>
      <geometry>
        <mesh filename="package://denso_robot_descriptions/robots/cvrb0609/meshes/J1.dae" scale="1 1 1"/>
      </geometry>
    </collision>
    <inertial>
      <mass value="1"/>
      <origin rpy="0.000000 0.000000 0.000000" xyz="0.000000 0.000000 0.000000"/>
      <inertia ixx="1" ixy="0" ixz="0" iyy="1" iyz="0" izz="1"/>
    </inertial>
  </link>
  <joint name="cobotta_pro_joint_1" type="revolute">
    <parent link="cobotta_pro_base_link"/>
    <child link="cobotta_pro_J1"/>
    <origin rpy="0.000000 0.000000 0.000000" xyz="0.000000 0.000000 0.101000"/>
    <axis xyz="-0.000000 -0.000000 1.000000"/>
    <limit effort="1" lower="-4.71238898038469" upper="4.71238898038469" velocity="0.397935"/>
    <dynamics damping="0" friction="0"/>
  </joint>
  <link name="cobotta_pro_J2">
    <visual>
      <origin rpy="0 0 0" xyz="0 0 0"/>
      <geometry>
        <mesh filename="package://denso_robot_descriptions/robots/cvrb0609/meshes/J2.dae" scale="1 1 1"/>
      </geometry>
    </visual>
    <collision>
      <origin rpy="0 0 0" xyz="0 0 0"/>
      <geometry>
        <mesh filename="package://denso_robot_descriptions/robots/cvrb0609/meshes/J2.dae" scale="1 1 1"/>
      </geometry>
    </collision>
    <inertial>
      <mass value="1"/>
      <origin rpy="0.000000 0.000000 0.000000" xyz="0.000000 0.000000 0.000000"/>
      <inertia ixx="1" ixy="0" ixz="0" iyy="1" iyz="0" izz="1"/>
    </inertial>
  </link>
  <joint name="cobotta_pro_joint_2" type="revolute">
    <parent link="cobotta_pro_J1"/>
    <child link="cobotta_pro_J2"/>
    <origin rpy="0.000000 0.000000 0.000000" xyz="0.000000 0.000000 0.109000"/>
    <axis xyz="-0.000000 1.000000 -0.000000"/>
    <limit effort="1" lower="-2.61799387799149" upper="2.61799387799149" velocity="0.331612"/>
    <dynamics damping="0" friction="0"/>
  </joint>
  <link name="cobotta_pro_J3">
    <visual>
      <origin rpy="0 0 0" xyz="0 0 0"/>
      <geometry>
        <mesh filename="package://denso_robot_descriptions/robots/cvrb0609/meshes/J3.dae" scale="1 1 1"/>
      </geometry>
    </visual>
    <collision>
      <origin rpy="0 0 0" xyz="0 0 0"/>
      <geometry>
        <mesh filename="package://denso_robot_descriptions/robots/cvrb0609/meshes/J3.dae" scale="1 1 1"/>
      </geometry>
    </collision>
    <inertial>
      <mass value="1"/>
      <origin rpy="0.000000 0.000000 0.000000" xyz="0.000000 0.000000 0.000000"/>
      <inertia ixx="1" ixy="0" ixz="0" iyy="1" iyz="0" izz="1"/>
    </inertial>
  </link>
  <joint name="cobotta_pro_joint_3" type="revolute">
    <parent link="cobotta_pro_J2"/>
    <child link="cobotta_pro_J3"/>
    <origin rpy="0.000000 0.000000 0.000000" xyz="0.000000 0.000000 0.510000"/>
    <axis xyz="-0.000000 1.000000 -0.000000"/>
    <limit effort="1" lower="-2.61799387799149" upper="2.61799387799149" velocity="0.397935"/>
    <dynamics damping="0" friction="0"/>
  </joint>
  <link name="cobotta_pro_J4">
    <visual>
      <origin rpy="0 0 0" xyz="0 0 0"/>
      <geometry>
        <mesh filename="package://denso_robot_descriptions/robots/cvrb0609/meshes/J4.dae" scale="1 1 1"/>
      </geometry>
    </visual>
    <collision>
      <origin rpy="0 0 0" xyz="0 0 0"/>
      <geometry>
        <mesh filename="package://denso_robot_descriptions/robots/cvrb0609/meshes/J4.dae" scale="1 1 1"/>
      </geometry>
    </collision>
    <inertial>
      <mass value="1"/>
      <origin rpy="0.000000 0.000000 0.000000" xyz="0.000000 0.000000 0.000000"/>
      <inertia ixx="1" ixy="0" ixz="0" iyy="1" iyz="0" izz="1"/>
    </inertial>
  </link>
  <joint name="cobotta_pro_joint_4" type="revolute">
    <parent link="cobotta_pro_J3"/>
    <child link="cobotta_pro_J4"/>
    <origin rpy="0.000000 0.000000 0.000000" xyz="0.000000 -0.030000 0.302000"/>
    <axis xyz="-0.000000 -0.000000 1.000000"/>
    <limit effort="1" lower="-4.71238898038469" upper="4.71238898038469" velocity="0.497418"/>
    <dynamics damping="0" friction="0"/>
  </joint>
  <link name="cobotta_pro_J5">
    <visual>
      <origin rpy="0 0 0" xyz="0 0 0"/>
      <geometry>
        <mesh filename="package://denso_robot_descriptions/robots/cvrb0609/meshes/J5.dae" scale="1 1 1"/>
      </geometry>
    </visual>
    <collision>
      <origin rpy="0 0 0" xyz="0 0 0"/>
      <geometry>
        <mesh filename="package://denso_robot_descriptions/robots/cvrb0609/meshes/J5.dae" scale="1 1 1"/>
      </geometry>
    </collision>
    <inertial>
      <mass value="1"/>
      <origin rpy="0.000000 0.000000 0.000000" xyz="0.000000 0.000000 0.000000"/>
      <inertia ixx="1" ixy="0" ixz="0" iyy="1" iyz="0" izz="1"/>
    </inertial>
  </link>
  <joint name="cobotta_pro_joint_5" type="revolute">
    <parent link="cobotta_pro_J4"/>
    <child link="cobotta_pro_J5"/>
    <origin rpy="0.000000 0.000000 0.000000" xyz="0.000000 0.030000 0.088000"/>
    <axis xyz="-0.000000 1.000000 -0.000000"/>
    <limit effort="1" lower="-2.61799387799149" upper="2.61799387799149" velocity="0.497418"/>
    <dynamics damping="0" friction="0"/>
  </joint>
  <link name="cobotta_pro_J6">
    <visual>
      <origin rpy="0 0 0" xyz="0 0 0"/>
      <geometry>
        <mesh filename="package://denso_robot_descriptions/robots/cvrb0609/meshes/J6.dae" scale="1 1 1"/>
      </geometry>
    </visual>
    <collision>
      <origin rpy="0 0 0" xyz="0 0 0"/>
      <geometry>
        <mesh filename="package://denso_robot_descriptions/robots/cvrb0609/meshes/J6.dae" scale="1 1 1"/>
      </geometry>
    </collision>
    <inertial>
      <mass value="1"/>
      <origin rpy="0.000000 0.000000 0.000000" xyz="0.000000 0.000000 0.000000"/>
      <inertia ixx="1" ixy="0" ixz="0" iyy="1" iyz="0" izz="1"/>
    </inertial>
  </link>
  <joint name="cobotta_pro_joint_6" type="revolute">
    <parent link="cobotta_pro_J5"/>
    <child link="cobotta_pro_J6"/>
    <origin rpy="0.000000 0.000000 0.000000" xyz="0.000000 0.120000 0.160000"/>
    <axis xyz="-0.000000 -0.000000 1.000000"/>
    <limit effort="1" lower="-6.28318530717959" upper="6.28318530717959" velocity="0.596903"/>
    <dynamics damping="0" friction="0"/>
  </joint>
  <ros2_control name="cobotta_pro_TopicBasedSystem" type="system">
    <hardware>
      <plugin>topic_based_ros2_control/TopicBasedSystem</plugin>
      <param name="joint_commands_topic">/topic_based_joint_commands</param>
      <param name="joint_states_topic">/topic_based_joint_states</param>
    </hardware>
    <joint name="cobotta_pro_joint_1">
      <command_interface name="position">
        <param name="min">-4.712389</param>
        <param name="max">4.712389</param>
      </command_interface>
      <command_interface name="acceleration">
        <param name="min">-0.310886</param>
        <param name="max">0.310886</param>
      </command_interface>
      <state_interface name="position"/>
      <state_interface name="velocity"/>
      <state_interface name="effort"/>
    </joint>
    <joint name="cobotta_pro_joint_2">
      <command_interface name="position">
        <param name="min">-2.617994</param>
        <param name="max">2.617994</param>
      </command_interface>
      <command_interface name="acceleration">
        <param name="min">-0.310886</param>
        <param name="max">0.310886</param>
      </command_interface>
      <state_interface name="position"/>
      <state_interface name="velocity"/>
      <state_interface name="effort"/>
    </joint>
    <joint name="cobotta_pro_joint_3">
      <command_interface name="position">
        <param name="min">-2.617994</param>
        <param name="max">2.617994</param>
      </command_interface>
      <command_interface name="acceleration">
        <param name="min">-0.621773</param>
        <param name="max">0.621773</param>
      </command_interface>
      <state_interface name="position"/>
      <state_interface name="velocity"/>
      <state_interface name="effort"/>
    </joint>
    <joint name="cobotta_pro_joint_4">
      <command_interface name="position">
        <param name="min">-4.712389</param>
        <param name="max">4.712389</param>
      </command_interface>
      <command_interface name="acceleration">
        <param name="min">-0.049741</param>
        <param name="max">0.049741</param>
      </command_interface>
      <state_interface name="position"/>
      <state_interface name="velocity"/>
      <state_interface name="effort"/>
    </joint>
    <joint name="cobotta_pro_joint_5">
      <command_interface name="position">
        <param name="min">-2.617994</param>
        <param name="max">2.617994</param>
      </command_interface>
      <command_interface name="acceleration">
        <param name="min">-0.690860</param>
        <param name="max">0.690860</param>
      </command_interface>
      <state_interface name="position"/>
      <state_interface name="velocity"/>
      <state_interface name="effort"/>
    </joint>
    <joint name="cobotta_pro_joint_6">
      <command_interface name="position">
        <param name="min">-6.283185</param>
        <param name="max">6.283185</param>
      </command_interface>
      <command_interface name="acceleration">
        <param name="min">-0.690860</param>
        <param name="max">0.690860</param>
      </command_interface>
      <state_interface name="position"/>
      <state_interface name="velocity"/>
      <state_interface name="effort"/>
    </joint>
  </ros2_control>
  <link name="world"/>
  <!-- base_plate link to cobotta link -->
  <joint name="joint_w" type="fixed">
    <origin rpy="0 0 1.5708" xyz="0 0 0"/>
    <parent link="robot_base_plate_link"/>
    <child link="cobotta_pro_base_link"/>
  </joint>
  <joint name="world_cell_joint" type="fixed">
    <parent link="world"/>
    <child link="cell_link"/>
    <origin rpy="0 0 0" xyz="0 0 0"/>
  </joint>
  <link name="cell_link">
    <inertial>
      <origin rpy="0 0 0" xyz="-0.010188 0.010903 0.93146"/>
      <mass value="1383.8"/>
      <inertia ixx="833.74" ixy="-0.082289" ixz="0.013641" iyy="819.21" iyz="0.033946" izz="522.69"/>
    </inertial>
    <visual>
      <origin rpy="0 0 0" xyz="0 0 0"/>
      <geometry>
        <mesh filename="package://techtory_cell_description/urdf/mesh/cell_link.STL"/>
      </geometry>
      <material name="">
        <color rgba="0.85098 0.72157 0.72157 1"/>
      </material>
    </visual>
    <collision>
      <origin rpy="0 0 0" xyz="0 0 0"/>
      <geometry>
        <mesh filename="package://techtory_cell_description/urdf/mesh/cell_link.STL"/>
      </geometry>
    </collision>
  </link>
  <link name="robot_base_plate_link">
    <inertial>
      <origin rpy="0 0 0" xyz="-0.010188 0.010903 0.93146"/>
      <mass value="1383.8"/>
      <inertia ixx="833.74" ixy="-0.082289" ixz="0.013641" iyy="819.21" iyz="0.033946" izz="522.69"/>
    </inertial>
    <visual>
      <origin rpy="0 0 0" xyz="0 0 0"/>
      <geometry>
        <mesh filename="package://techtory_cell_description/urdf/mesh/robot_base_link.STL" scale="0.9 0.9 1.5"/>
      </geometry>
      <material name="">
        <color rgba="0.85098 0.72157 0.72157 1"/>
      </material>
    </visual>
    <collision>
      <origin rpy="0 0 0" xyz="0 0 0"/>
      <geometry>
        <mesh filename="package://techtory_cell_description/urdf/mesh/robot_base_link.STL" scale="0.9 0.9 1.5"/>
      </geometry>
    </collision>
  </link>
  <joint name="robot_base_plate_link_joint" type="fixed">
    <parent link="cell_link"/>
    <child link="robot_base_plate_link"/>
    <origin rpy="0 0 0" xyz="0 -0.3 0.93"/>
  </joint>
    <!-- virtual end-effector link for cobotta_proJ6 -->
  <link name="tool_tip0"/>
  <joint name="tool_tip0_virtual_joint" type="fixed">
    <parent link="cobotta_pro_J6"/>
    <child link="tool_tip0"/>
    <origin rpy="0 0 0" xyz="0 0 0"/>
  </joint>
  <ros2_control name="FakeSystem" type="system">
    <hardware>
      <plugin>topic_based_ros2_control/TopicBasedSystem</plugin>
      <param name="joint_command_topic">/topic_based_joint_commands</param>
      <param name="joint_state_topic">/topic_based_joint_states</param>
    </hardware>
    <joint name="cobotta_pro_joint_1">
      <command_interface name="position"/>
      <command_interface name="acceleration">
        <param name="min">0</param>
        <param name="max">0.310886</param>
      </command_interface>
      <state_interface name="position">
        <param name="initial_value">-0.942</param>
      </state_interface>
      <state_interface name="velocity"/>
    </joint>
    <joint name="cobotta_pro_joint_2">
      <command_interface name="position"/>
      <command_interface name="acceleration">
        <param name="min">0</param>
        <param name="max">0.310886</param>
      </command_interface>
      <state_interface name="position">
        <param name="initial_value">0</param>
      </state_interface>
      <state_interface name="velocity"/>
    </joint>
    <joint name="cobotta_pro_joint_3">
      <command_interface name="position"/>
      <command_interface name="acceleration">
        <param name="min">0</param>
        <param name="max">0.621773</param>
      </command_interface>
      <state_interface name="position">
        <param name="initial_value">-1.571</param>
      </state_interface>
      <state_interface name="velocity"/>
    </joint>
    <joint name="cobotta_pro_joint_4">
      <command_interface name="position"/>
      <command_interface name="acceleration">
        <param name="min">0</param>
        <param name="max">0.049741</param>
      </command_interface>
      <state_interface name="position">
        <param name="initial_value">-3.031</param>
      </state_interface>
      <state_interface name="velocity"/>
    </joint>
    <joint name="cobotta_pro_joint_5">
      <command_interface name="position"/>
      <command_interface name="acceleration">
        <param name="min">0</param>
        <param name="max">0.690860</param>
      </command_interface>
      <state_interface name="position">
        <param name="initial_value">1.543</param>
      </state_interface>
      <state_interface name="velocity"/>
    </joint>
    <joint name="cobotta_pro_joint_6">
      <command_interface name="position"/>
      <command_interface name="acceleration">
        <param name="min">0</param>
        <param name="max">0.690860</param>
      </command_interface>
      <state_interface name="position">
        <param name="initial_value">0.102</param>
      </state_interface>
      <state_interface name="velocity"/>
    </joint>
  </ros2_control>
</robot>
