<?xml version="1.0"?>
<!-- =================================================================================== -->
<!-- |    This document was autogenerated by xacro from cvrb0609.urdf.xacro            | -->
<!-- |    EDITING THIS FILE BY HAND IS NOT RECOMMENDED                                 | -->
<!-- =================================================================================== -->
<robot name="cvrb0609" xmlns:xacro="http://www.ros.org/wiki/xacro">
  
  <xacro:include filename="$(find cvrb0609_description)/urdf/schmalz_ecbpmi.xacro"/>

  <xacro:macro name="cvrb0609" params="prefix">

    <!--
    Base Denso robot xacro macro.

    NOTE this is NOT a URDF. It cannot directly be loaded by consumers
    expecting a flattened '.urdf' file. See the top-level '.xacro' for that
    (but note that .xacro must still be processed by the xacro command).

    This file models the base kinematic chain of a Denso robot.

    Author DENSO WAVE INCORPORATED
  -->
    <!--
    NOTE the macro defined in this file is NOT part of the public API of this
          package. Users CANNOT rely on this file being available, or stored in
          this location. Nor can they rely on the existence of the macro.
  -->

    <link name="${prefix}base_link">
      <visual>
        <origin rpy="0 0 0" xyz="0 0 0"/>
        <geometry>
          <mesh filename="package://cvrb0609_description/meshes//base_link.dae" scale="1 1 1"/>
        </geometry>
      </visual>
      <collision>
        <origin rpy="0 0 0" xyz="0 0 0"/>
        <geometry>
          <mesh filename="package://cvrb0609_description/meshes//base_link.dae" scale="1 1 1"/>
        </geometry>
      </collision>
      <inertial>
        <mass value="1"/>
        <origin rpy="0.000000 0.000000 0.000000" xyz="0.000000 0.000000 0.000000"/>
        <inertia ixx="1" ixy="0" ixz="0" iyy="1" iyz="0" izz="1"/>
      </inertial>
    </link>
    <link name="${prefix}J1">
      <visual>
        <origin rpy="0 0 0" xyz="0 0 0"/>
        <geometry>
          <mesh filename="package://cvrb0609_description/meshes//J1.dae" scale="1 1 1"/>
        </geometry>
      </visual>
      <collision>
        <origin rpy="0 0 0" xyz="0 0 0"/>
        <geometry>
          <mesh filename="package://cvrb0609_description/meshes//J1.dae" scale="1 1 1"/>
        </geometry>
      </collision>
      <inertial>
        <mass value="1"/>
        <origin rpy="0.000000 0.000000 0.000000" xyz="0.000000 0.000000 0.000000"/>
        <inertia ixx="1" ixy="0" ixz="0" iyy="1" iyz="0" izz="1"/>
      </inertial>
    </link>
    <joint name="${prefix}joint_1" type="revolute">
      <parent link="${prefix}base_link"/>
      <child link="${prefix}J1"/>
      <origin rpy="0.000000 0.000000 0.000000" xyz="0.000000 0.000000 0.101000"/>
      <axis xyz="-0.000000 -0.000000 1.000000"/>
      <limit effort="1" lower="-4.71238898038469" upper="4.71238898038469" velocity="0.397935"/>
      <dynamics damping="0" friction="0"/>
    </joint>
    <link name="${prefix}J2">
      <visual>
        <origin rpy="0 0 0" xyz="0 0 0"/>
        <geometry>
          <mesh filename="package://cvrb0609_description/meshes//J2.dae" scale="1 1 1"/>
        </geometry>
      </visual>
      <collision>
        <origin rpy="0 0 0" xyz="0 0 0"/>
        <geometry>
          <mesh filename="package://cvrb0609_description/meshes//J2.dae" scale="1 1 1"/>
        </geometry>
      </collision>
      <inertial>
        <mass value="1"/>
        <origin rpy="0.000000 0.000000 0.000000" xyz="0.000000 0.000000 0.000000"/>
        <inertia ixx="1" ixy="0" ixz="0" iyy="1" iyz="0" izz="1"/>
      </inertial>
    </link>
    <joint name="${prefix}joint_2" type="revolute">
      <parent link="${prefix}J1"/>
      <child link="${prefix}J2"/>
      <origin rpy="0.000000 0.000000 0.000000" xyz="0.000000 0.000000 0.109000"/>
      <axis xyz="-0.000000 1.000000 -0.000000"/>
      <limit effort="1" lower="-2.61799387799149" upper="2.61799387799149" velocity="0.331612"/>
      <dynamics damping="0" friction="0"/>
    </joint>
    <link name="${prefix}J3">
      <visual>
        <origin rpy="0 0 0" xyz="0 0 0"/>
        <geometry>
          <mesh filename="package://cvrb0609_description/meshes//J3.dae" scale="1 1 1"/>
        </geometry>
      </visual>
      <collision>
        <origin rpy="0 0 0" xyz="0 0 0"/>
        <geometry>
          <mesh filename="package://cvrb0609_description/meshes//J3.dae" scale="1 1 1"/>
        </geometry>
      </collision>
      <inertial>
        <mass value="1"/>
        <origin rpy="0.000000 0.000000 0.000000" xyz="0.000000 0.000000 0.000000"/>
        <inertia ixx="1" ixy="0" ixz="0" iyy="1" iyz="0" izz="1"/>
      </inertial>
    </link>
    <joint name="${prefix}joint_3" type="revolute">
      <parent link="${prefix}J2"/>
      <child link="${prefix}J3"/>
      <origin rpy="0.000000 0.000000 0.000000" xyz="0.000000 0.000000 0.510000"/>
      <axis xyz="-0.000000 1.000000 -0.000000"/>
      <limit effort="1" lower="-2.61799387799149" upper="2.61799387799149" velocity="0.397935"/>
      <dynamics damping="0" friction="0"/>
    </joint>
    <link name="${prefix}J4">
      <visual>
        <origin rpy="0 0 0" xyz="0 0 0"/>
        <geometry>
          <mesh filename="package://cvrb0609_description/meshes//J4.dae" scale="1 1 1"/>
        </geometry>
      </visual>
      <collision>
        <origin rpy="0 0 0" xyz="0 0 0"/>
        <geometry>
          <mesh filename="package://cvrb0609_description/meshes//J4.dae" scale="1 1 1"/>
        </geometry>
      </collision>
      <inertial>
        <mass value="1"/>
        <origin rpy="0.000000 0.000000 0.000000" xyz="0.000000 0.000000 0.000000"/>
        <inertia ixx="1" ixy="0" ixz="0" iyy="1" iyz="0" izz="1"/>
      </inertial>
    </link>
    <joint name="${prefix}joint_4" type="revolute">
      <parent link="${prefix}J3"/>
      <child link="${prefix}J4"/>
      <origin rpy="0.000000 0.000000 0.000000" xyz="0.000000 -0.030000 0.302000"/>
      <axis xyz="-0.000000 -0.000000 1.000000"/>
      <limit effort="1" lower="-4.71238898038469" upper="4.71238898038469" velocity="0.497418"/>
      <dynamics damping="0" friction="0"/>
    </joint>
    <link name="${prefix}J5">
      <visual>
        <origin rpy="0 0 0" xyz="0 0 0"/>
        <geometry>
          <mesh filename="package://cvrb0609_description/meshes//J5.dae" scale="1 1 1"/>
        </geometry>
      </visual>
      <collision>
        <origin rpy="0 0 0" xyz="0 0 0"/>
        <geometry>
          <mesh filename="package://cvrb0609_description/meshes//J5.dae" scale="1 1 1"/>
        </geometry>
      </collision>
      <inertial>
        <mass value="1"/>
        <origin rpy="0.000000 0.000000 0.000000" xyz="0.000000 0.000000 0.000000"/>
        <inertia ixx="1" ixy="0" ixz="0" iyy="1" iyz="0" izz="1"/>
      </inertial>
    </link>
    <joint name="${prefix}joint_5" type="revolute">
      <parent link="${prefix}J4"/>
      <child link="${prefix}J5"/>
      <origin rpy="0.000000 0.000000 0.000000" xyz="0.000000 0.030000 0.088000"/>
      <axis xyz="-0.000000 1.000000 -0.000000"/>
      <limit effort="1" lower="-2.61799387799149" upper="2.61799387799149" velocity="0.497418"/>
      <dynamics damping="0" friction="0"/>
    </joint>
    <link name="${prefix}J6">
      <visual>
        <origin rpy="0 0 0" xyz="0 0 0"/>
        <geometry>
          <mesh filename="package://cvrb0609_description/meshes//J6.dae" scale="1 1 1"/>
        </geometry>
      </visual>
      <collision>
        <origin rpy="0 0 0" xyz="0 0 0"/>
        <geometry>
          <mesh filename="package://cvrb0609_description/meshes//J6.dae" scale="1 1 1"/>
        </geometry>
      </collision>
      <inertial>
        <mass value="1"/>
        <origin rpy="0.000000 0.000000 0.000000" xyz="0.000000 0.000000 0.000000"/>
        <inertia ixx="1" ixy="0" ixz="0" iyy="1" iyz="0" izz="1"/>
      </inertial>
    </link>
    <joint name="${prefix}joint_6" type="revolute">
      <parent link="${prefix}J5"/>
      <child link="${prefix}J6"/>
      <origin rpy="0.000000 0.000000 0.000000" xyz="0.000000 0.120000 0.160000"/>
      <axis xyz="-0.000000 -0.000000 1.000000"/>
      <limit effort="1" lower="-6.28318530717959" upper="6.28318530717959" velocity="0.596903"/>
      <dynamics damping="0" friction="0"/>
    </joint>


      
      <!-- Instantiate Schmalz_ecbpmi Gripper -->

    <xacro:schmalz_ecbpmi
      parent="${prefix}J6"
      name="schmalz_ecbpmi"
      prefix="">
      <origin xyz="0 0 0" rpy="0 0 0" />
    </xacro:schmalz_ecbpmi>



  </xacro:macro>
</robot>
