<mujoco model="techtory_demo_description">
  <compiler angle="radian" meshdir="assets/" texturedir="assets/"/>

  <asset>
    <mesh name="base_link" content_type="model/obj" file="full/base_link.obj"/>
    <mesh name="J1" content_type="model/obj" file="full/J1.obj"/>
    <mesh name="J2" content_type="model/obj" file="full/J2.obj"/>
    <mesh name="J3" content_type="model/obj" file="full/J3.obj"/>
    <mesh name="J4" content_type="model/obj" file="full/J4.obj"/>
    <mesh name="J5" content_type="model/obj" file="full/J5.obj"/>
    <mesh name="J6" content_type="model/obj" file="full/J6.obj"/>
    <mesh name="Schmalz_ECBPMi" content_type="model/stl" file="full/Schmalz_ECBPMi.stl"/>
    <mesh name="cell_link" content_type="model/obj" file="full/cell_link.obj"/>
    <mesh name="robot_base_link" content_type="model/stl" file="full/robot_base_link.stl" scale="0.9 0.9 1.5"/>
  </asset>

  <worldbody>
    <geom type="mesh" contype="0" conaffinity="0" group="1" density="0" rgba="0.85098 0.72157 0.72157 1" mesh="cell_link"/>
    <geom pos="0 -0.3 0.93" quat="1 0 0 0" type="mesh" contype="0" conaffinity="0" group="1" density="0" rgba="0.85098 0.72157 0.72157 1" mesh="robot_base_link"/>
    <geom pos="0 -0.3 0.93" quat="1 0 0 0" type="mesh" contype="0" conaffinity="0" group="1" density="0" mesh="base_link"/>
    <body name="cobotta_pro_J1" pos="0 -0.3 1.031">
      <inertial pos="0 0 0" mass="1" diaginertia="1 1 1"/>
      <joint name="cobotta_pro_joint_1" pos="0 0 0" axis="0 0 1" range="-4.71239 4.71239" actuatorfrcrange="-1 1"/>
      <geom type="mesh" contype="0" conaffinity="0" group="1" density="0" mesh="J1"/>
      <body name="cobotta_pro_J2" pos="0 0 0.109">
        <inertial pos="0 0 0" mass="1" diaginertia="1 1 1"/>
        <joint name="cobotta_pro_joint_2" pos="0 0 0" axis="0 1 0" range="-2.61799 2.61799" actuatorfrcrange="-1 1"/>
        <geom type="mesh" contype="0" conaffinity="0" group="1" density="0" mesh="J2"/>
        <body name="cobotta_pro_J3" pos="0 0 0.51">
          <inertial pos="0 0 0" mass="1" diaginertia="1 1 1"/>
          <joint name="cobotta_pro_joint_3" pos="0 0 0" axis="0 1 0" range="-2.61799 2.61799" actuatorfrcrange="-1 1"/>
          <geom type="mesh" contype="0" conaffinity="0" group="1" density="0" mesh="J3"/>
          <body name="cobotta_pro_J4" pos="0 -0.03 0.302">
            <inertial pos="0 0 0" mass="1" diaginertia="1 1 1"/>
            <joint name="cobotta_pro_joint_4" pos="0 0 0" axis="0 0 1" range="-4.71239 4.71239" actuatorfrcrange="-1 1"/>
            <geom type="mesh" contype="0" conaffinity="0" group="1" density="0" mesh="J4"/>
            <body name="cobotta_pro_J5" pos="0 0.03 0.088">
              <inertial pos="0 0 0" mass="1" diaginertia="1 1 1"/>
              <joint name="cobotta_pro_joint_5" pos="0 0 0" axis="0 1 0" range="-2.61799 2.61799" actuatorfrcrange="-1 1"/>
              <geom type="mesh" contype="0" conaffinity="0" group="1" density="0" mesh="J5"/>
              <body name="cobotta_pro_J6" pos="0 0.12 0.16">
                <inertial pos="0 0 0.0133586" mass="1.324" diaginertia="1.00109 1.00109 1.00016"/>
                <joint name="cobotta_pro_joint_6" pos="0 0 0" axis="0 0 1" range="-6.28319 6.28319" actuatorfrcrange="-1 1"/>
                <geom type="mesh" contype="0" conaffinity="0" group="1" density="0" mesh="J6"/>
                <geom size="0.0155 0.0185" pos="0 0 0.0185" type="cylinder" contype="0" conaffinity="0" group="1" density="0" rgba="0 0.2 1 1"/>
                <geom pos="0 0 0.0707" quat="0.707107 -0.707107 0 0" type="mesh" contype="0" conaffinity="0" group="1" density="0" rgba="0 0.9 0.3 1" mesh="Schmalz_ECBPMi"/>
              </body>
            </body>
          </body>
        </body>
      </body>
    </body>
  </worldbody>
</mujoco>
