<mujoco model="techtory_cobotta_workcell">
  <compiler angle="radian" meshdir="assets/" texturedir="assets/"/>
  <option integrator="implicitfast"/>
  <default>
    <default class="cobotta">
      <joint damping="8" armature="0.08" frictionloss="0.2"/>
      <default class="visual">
        <geom type="mesh" group="2" contype="0" conaffinity="0" density="0"/>
      </default>
      <default class="collision">
        <geom type="mesh" group="3" mass="0" density="0"/>
      </default>
    </default>
  </default>
  <asset>
    <mesh name="Schmalz_ECBPMi" content_type="model/stl" file="full/Schmalz_ECBPMi.stl"/>
    <mesh name="robot_base_link" content_type="model/stl" file="full/robot_base_link.stl" scale="0.9 0.9 1.5"/>
    <mesh file="full/base_link/base_link.obj" scale="1.0 1.0 1.0"/>
    <material name="material_m0_0" specular="0.20000000000000004" shininess="1.0" rgba="0.75294118 0.75294118 0.75294118 1.0"/>
    <mesh file="full/J1/J1.obj" scale="1.0 1.0 1.0"/>
    <material name="material_m1_0" specular="0.20000000000000004" shininess="1.0" rgba="0.75294118 0.75294118 0.75294118 1.0"/>
    <mesh file="full/J2/J2.obj" scale="1.0 1.0 1.0"/>
    <material name="material_m2_0" specular="0.20000000000000004" shininess="1.0" rgba="0.75294118 0.75294118 0.75294118 1.0"/>
    <mesh file="full/J3/J3.obj" scale="1.0 1.0 1.0"/>
    <material name="material_m3_0" specular="0.20000000000000004" shininess="1.0" rgba="0.75294118 0.75294118 0.75294118 1.0"/>
    <mesh file="full/J4/J4.obj" scale="1.0 1.0 1.0"/>
    <material name="material_m4_0" specular="0.20000000000000004" shininess="1.0" rgba="0.75294118 0.75294118 0.75294118 1.0"/>
    <mesh file="full/J5/J5.obj" scale="1.0 1.0 1.0"/>
    <material name="material_m5_0" specular="0.20000000000000004" shininess="1.0" rgba="0.75294118 0.75294118 0.75294118 1.0"/>
    <mesh file="full/J6/J6.obj" scale="1.0 1.0 1.0"/>
    <material name="material_m6_0" specular="0.20000000000000004" shininess="1.0" rgba="0.20000000 0.20000000 0.20000000 1.0"/>
    <mesh file="full/cell_link/cell_link.obj" scale="1.0 1.0 1.0"/>
    <material name="mtl_m7" specular="0.20000000000000004" shininess="1.0" rgba="0.85098039 0.72156863 0.72156863 1.0"/>
  </asset>
  <worldbody>
    <body name="cobotta_pro_J1" pos="0 -0.3 1.031" quat="0.707107 0 0 0.707107" childclass="cobotta">
      <inertial pos="0 0 0" mass="1" diaginertia="1 1 1"/>
      <joint name="cobotta_pro_joint_1" pos="0 0 0" axis="0 0 1" range="-4.71239 4.71239" actuatorfrcrange="-600 600"/>
      <body name="cobotta_pro_J2" pos="0 0 0.109">
        <inertial pos="0 0 0" mass="1" diaginertia="1 1 1"/>
        <joint name="cobotta_pro_joint_2" pos="0 0 0" axis="0 1 0" range="-2.61799 2.61799" actuatorfrcrange="-900 900" damping="14"/>
        <body name="cobotta_pro_J3" pos="0 0 0.51">
          <inertial pos="0 0 0" mass="1" diaginertia="1 1 1"/>
          <joint name="cobotta_pro_joint_3" pos="0 0 0" axis="0 1 0" range="-2.61799 2.61799" actuatorfrcrange="-700 700" damping="12"/>
          <body name="cobotta_pro_J4" pos="0 -0.03 0.302">
            <inertial pos="0 0 0" mass="1" diaginertia="1 1 1"/>
            <joint name="cobotta_pro_joint_4" pos="0 0 0" axis="0 0 1" range="-4.71239 4.71239" actuatorfrcrange="-250 250"/>
            <body name="cobotta_pro_J5" pos="0 0.03 0.088">
              <inertial pos="0 0 0" mass="1" diaginertia="1 1 1"/>
              <joint name="cobotta_pro_joint_5" pos="0 0 0" axis="0 1 0" range="-2.61799 2.61799" actuatorfrcrange="-180 180"/>
              <body name="cobotta_pro_J6" pos="0 0.12 0.16">
                <inertial pos="0 0 0.0133586" mass="1.324" diaginertia="1.00109 1.00109 1.00016"/>
                <joint name="cobotta_pro_joint_6" pos="0 0 0" axis="0 0 1" range="-6.28319 6.28319" actuatorfrcrange="-100 100"/>
                <geom material="material_m6_0" mesh="J6" class="visual"/>
                <geom mesh="J6" class="collision"/>
                <geom size="0.0155 0.0185" pos="0 0 0.0185" type="cylinder" class="collision"/>
                <geom size="0.0155 0.0185" pos="0 0 0.0185" type="cylinder" rgba="0 0.2 1 1" class="visual"/>
                <geom pos="0 0 0.0707" quat="0.707107 -0.707107 0 0" type="mesh" mesh="Schmalz_ECBPMi" class="collision"/>
                <geom pos="0 0 0.0707" quat="0.707107 -0.707107 0 0" type="mesh" rgba="0 0.9 0.3 1" mesh="Schmalz_ECBPMi" class="visual"/>
                <site name="cobotta_pro_J6" pos="0 0 0" quat="1.0 0 0 0"/>
                <site name="schmalz_ecbpmi_base_link" pos="0 0 0" quat="1.0 0 0 0"/>
                <site name="schmalz_ecbpmi_body_link" pos="0 0 0.052199999999999996" quat="1.0 0 0 0"/>
                <site name="tool_tip" pos="0 0 0.1004" quat="1.0 0 0 0"/>
              </body>
              <geom material="material_m5_0" mesh="J5" class="visual"/>
              <geom mesh="J5" class="collision"/>
              <site name="cobotta_pro_J5" pos="0 0 0" quat="1.0 0 0 0"/>
            </body>
            <geom material="material_m4_0" mesh="J4" class="visual"/>
            <geom mesh="J4" class="collision"/>
            <site name="cobotta_pro_J4" pos="0 0 0" quat="1.0 0 0 0"/>
          </body>
          <geom material="material_m3_0" mesh="J3" class="visual"/>
          <geom mesh="J3" class="collision"/>
          <site name="cobotta_pro_J3" pos="0 0 0" quat="1.0 0 0 0"/>
        </body>
        <geom material="material_m2_0" mesh="J2" class="visual"/>
        <geom mesh="J2" class="collision"/>
        <site name="cobotta_pro_J2" pos="0 0 0" quat="1.0 0 0 0"/>
      </body>
      <geom material="material_m1_0" mesh="J1" class="visual"/>
      <geom mesh="J1" class="collision"/>
      <site name="cobotta_pro_J1" pos="0 0 0" quat="1.0 0 0 0"/>
    </body>
    <geom material="material_m0_0" mesh="base_link" class="visual" pos="0 -0.3 0.93" quat="0.707107 0 0 0.707107"/>
    <geom mesh="base_link" class="collision" pos="0 -0.3 0.93" quat="0.707107 0 0 0.707107"/>
    <body name="cell_link_body">
      <geom material="mtl_m7" mesh="cell_link" class="visual"/>
      <geom mesh="cell_link" class="collision"/>
    </body>
    <geom pos="0 -0.3 0.93" quat="0.707107 0 0 0.707107" type="mesh" mesh="robot_base_link" class="collision"/>
    <geom pos="0 -0.3 0.93" quat="0.707107 0 0 0.707107" type="mesh" rgba="0.85098 0.72157 0.72157 1" mesh="robot_base_link" class="visual"/>
    <site name="world" pos="0 0 0" quat="1.0 0 0 0"/>
    <site name="cobotta_pro_base_link" pos="0 -0.3 0.93" quat="0.707107 0 0 0.707107"/>
    <site name="cell_link" pos="0 0 0" quat="1.0 0 0 0"/>
    <site name="robot_base_plate_link" pos="0 -0.3 0.93" quat="0.707107 0 0 0.707107"/>
  </worldbody>
  <actuator>
    <position class="cobotta" name="cobotta_pro_joint_1" joint="cobotta_pro_joint_1" kp="3200" kv="320" ctrllimited="true" ctrlrange="-4.71239 4.71239" forcelimited="true" forcerange="-600 600"/>
    <position class="cobotta" name="cobotta_pro_joint_2" joint="cobotta_pro_joint_2" kp="3600" kv="360" ctrllimited="true" ctrlrange="-2.61799 2.61799" forcelimited="true" forcerange="-900 900"/>
    <position class="cobotta" name="cobotta_pro_joint_3" joint="cobotta_pro_joint_3" kp="3200" kv="320" ctrllimited="true" ctrlrange="-2.61799 2.61799" forcelimited="true" forcerange="-700 700"/>
    <position class="cobotta" name="cobotta_pro_joint_4" joint="cobotta_pro_joint_4" kp="2200" kv="220" ctrllimited="true" ctrlrange="-4.71239 4.71239" forcelimited="true" forcerange="-250 250"/>
    <position class="cobotta" name="cobotta_pro_joint_5" joint="cobotta_pro_joint_5" kp="1400" kv="140" ctrllimited="true" ctrlrange="-2.61799 2.61799" forcelimited="true" forcerange="-180 180"/>
    <position class="cobotta" name="cobotta_pro_joint_6" joint="cobotta_pro_joint_6" kp="900" kv="90" ctrllimited="true" ctrlrange="-6.28319 6.28319" forcelimited="true" forcerange="-100 100"/>
  </actuator>
  <contact>
    <exclude body1="cobotta_pro_J1" body2="cobotta_pro_J2"/>
    <exclude body1="cobotta_pro_J2" body2="cobotta_pro_J3"/>
    <exclude body1="cobotta_pro_J3" body2="cobotta_pro_J4"/>
    <exclude body1="cobotta_pro_J4" body2="cobotta_pro_J5"/>
    <exclude body1="cobotta_pro_J5" body2="cobotta_pro_J6"/>
    <exclude body1="cobotta_pro_J1" body2="cell_link_body"/>
    <exclude body1="cobotta_pro_J2" body2="cell_link_body"/>
    <exclude body1="cobotta_pro_J3" body2="cell_link_body"/>
    <exclude body1="cobotta_pro_J4" body2="cell_link_body"/>
    <exclude body1="cobotta_pro_J5" body2="cell_link_body"/>
    <exclude body1="cobotta_pro_J6" body2="cell_link_body"/>
  </contact>
  <keyframe>
    <key name="initial" time="0" qpos="1.5 0.4 1.2 0 0 0" qvel="0 0 0 0 0 0" ctrl="1.5 0.4 1.2 0 0 0"/>
  </keyframe>
</mujoco>
