<?xml version="1.0" ?>
<!-- =================================================================================== -->
<!-- |    This document was autogenerated by xacro from techtory_cobotta_workcell.urdf.xacro | -->
<!-- |    EDITING THIS FILE BY HAND IS NOT RECOMMENDED                                 | -->
<!-- =================================================================================== -->
<robot name="techtory_demo_description">
  <!--
    Base Denso robot xacro macro.

    NOTE this is NOT a URDF. It cannot directly be loaded by consumers
    expecting a flattened '.urdf' file. See the top-level '.xacro' for that
    (but note that .xacro must still be processed by the xacro command).

    This file models the base kinematic chain of a Denso robot.

    Author DENSO WAVE INCORPORATED
  -->
  <!-- <link name="world"/>
		<joint name="$(arg namespace)joint_w" type="fixed">
			<parent link="world"/>
			<child link="$(arg namespace)base_link"/>
		</joint> -->
  <link name="cobotta_pro_base_link">
    <visual>
      <origin rpy="0 0 0" xyz="0 0 0"/>
      <geometry>
        <mesh filename="package://denso_robot_descriptions/robots/cvrb0609/meshes/base_link.dae" scale="1 1 1"/>
      </geometry>
    </visual>
    <collision>
      <origin rpy="0 0 0" xyz="0 0 0"/>
      <geometry>
        <mesh filename="package://denso_robot_descriptions/robots/cvrb0609/meshes/base_link.dae" scale="1 1 1"/>
      </geometry>
    </collision>
    <inertial>
      <mass value="1"/>
      <origin rpy="0.000000 0.000000 0.000000" xyz="0.000000 0.000000 0.000000"/>
      <inertia ixx="1" ixy="0" ixz="0" iyy="1" iyz="0" izz="1"/>
    </inertial>
  </link>
  <link name="cobotta_pro_J1">
    <visual>
      <origin rpy="0 0 0" xyz="0 0 0"/>
      <geometry>
        <mesh filename="package://denso_robot_descriptions/robots/cvrb0609/meshes/J1.dae" scale="1 1 1"/>
      </geometry>
    </visual>
    <collision>
      <origin rpy="0 0 0" xyz="0 0 0"/>
      <geometry>
        <mesh filename="package://denso_robot_descriptions/robots/cvrb0609/meshes/J1.dae" scale="1 1 1"/>
      </geometry>
    </collision>
    <inertial>
      <mass value="1"/>
      <origin rpy="0.000000 0.000000 0.000000" xyz="0.000000 0.000000 0.000000"/>
      <inertia ixx="1" ixy="0" ixz="0" iyy="1" iyz="0" izz="1"/>
    </inertial>
  </link>
  <joint name="cobotta_pro_joint_1" type="revolute">
    <parent link="cobotta_pro_base_link"/>
    <child link="cobotta_pro_J1"/>
    <origin rpy="0.000000 0.000000 0.000000" xyz="0.000000 0.000000 0.101000"/>
    <axis xyz="-0.000000 -0.000000 1.000000"/>
    <limit effort="1" lower="-4.71238898038469" upper="4.71238898038469" velocity="0.397935"/>
    <dynamics damping="0" friction="0"/>
  </joint>
  <link name="cobotta_pro_J2">
    <visual>
      <origin rpy="0 0 0" xyz="0 0 0"/>
      <geometry>
        <mesh filename="package://denso_robot_descriptions/robots/cvrb0609/meshes/J2.dae" scale="1 1 1"/>
      </geometry>
    </visual>
    <collision>
      <origin rpy="0 0 0" xyz="0 0 0"/>
      <geometry>
        <mesh filename="package://denso_robot_descriptions/robots/cvrb0609/meshes/J2.dae" scale="1 1 1"/>
      </geometry>
    </collision>
    <inertial>
      <mass value="1"/>
      <origin rpy="0.000000 0.000000 0.000000" xyz="0.000000 0.000000 0.000000"/>
      <inertia ixx="1" ixy="0" ixz="0" iyy="1" iyz="0" izz="1"/>
    </inertial>
  </link>
  <joint name="cobotta_pro_joint_2" type="revolute">
    <parent link="cobotta_pro_J1"/>
    <child link="cobotta_pro_J2"/>
    <origin rpy="0.000000 0.000000 0.000000" xyz="0.000000 0.000000 0.109000"/>
    <axis xyz="-0.000000 1.000000 -0.000000"/>
    <limit effort="1" lower="-2.61799387799149" upper="2.61799387799149" velocity="0.331612"/>
    <dynamics damping="0" friction="0"/>
  </joint>
  <link name="cobotta_pro_J3">
    <visual>
      <origin rpy="0 0 0" xyz="0 0 0"/>
      <geometry>
        <mesh filename="package://denso_robot_descriptions/robots/cvrb0609/meshes/J3.dae" scale="1 1 1"/>
      </geometry>
    </visual>
    <collision>
      <origin rpy="0 0 0" xyz="0 0 0"/>
      <geometry>
        <mesh filename="package://denso_robot_descriptions/robots/cvrb0609/meshes/J3.dae" scale="1 1 1"/>
      </geometry>
    </collision>
    <inertial>
      <mass value="1"/>
      <origin rpy="0.000000 0.000000 0.000000" xyz="0.000000 0.000000 0.000000"/>
      <inertia ixx="1" ixy="0" ixz="0" iyy="1" iyz="0" izz="1"/>
    </inertial>
  </link>
  <joint name="cobotta_pro_joint_3" type="revolute">
    <parent link="cobotta_pro_J2"/>
    <child link="cobotta_pro_J3"/>
    <origin rpy="0.000000 0.000000 0.000000" xyz="0.000000 0.000000 0.510000"/>
    <axis xyz="-0.000000 1.000000 -0.000000"/>
    <limit effort="1" lower="-2.61799387799149" upper="2.61799387799149" velocity="0.397935"/>
    <dynamics damping="0" friction="0"/>
  </joint>
  <link name="cobotta_pro_J4">
    <visual>
      <origin rpy="0 0 0" xyz="0 0 0"/>
      <geometry>
        <mesh filename="package://denso_robot_descriptions/robots/cvrb0609/meshes/J4.dae" scale="1 1 1"/>
      </geometry>
    </visual>
    <collision>
      <origin rpy="0 0 0" xyz="0 0 0"/>
      <geometry>
        <mesh filename="package://denso_robot_descriptions/robots/cvrb0609/meshes/J4.dae" scale="1 1 1"/>
      </geometry>
    </collision>
    <inertial>
      <mass value="1"/>
      <origin rpy="0.000000 0.000000 0.000000" xyz="0.000000 0.000000 0.000000"/>
      <inertia ixx="1" ixy="0" ixz="0" iyy="1" iyz="0" izz="1"/>
    </inertial>
  </link>
  <joint name="cobotta_pro_joint_4" type="revolute">
    <parent link="cobotta_pro_J3"/>
    <child link="cobotta_pro_J4"/>
    <origin rpy="0.000000 0.000000 0.000000" xyz="0.000000 -0.030000 0.302000"/>
    <axis xyz="-0.000000 -0.000000 1.000000"/>
    <limit effort="1" lower="-4.71238898038469" upper="4.71238898038469" velocity="0.497418"/>
    <dynamics damping="0" friction="0"/>
  </joint>
  <link name="cobotta_pro_J5">
    <visual>
      <origin rpy="0 0 0" xyz="0 0 0"/>
      <geometry>
        <mesh filename="package://denso_robot_descriptions/robots/cvrb0609/meshes/J5.dae" scale="1 1 1"/>
      </geometry>
    </visual>
    <collision>
      <origin rpy="0 0 0" xyz="0 0 0"/>
      <geometry>
        <mesh filename="package://denso_robot_descriptions/robots/cvrb0609/meshes/J5.dae" scale="1 1 1"/>
      </geometry>
    </collision>
    <inertial>
      <mass value="1"/>
      <origin rpy="0.000000 0.000000 0.000000" xyz="0.000000 0.000000 0.000000"/>
      <inertia ixx="1" ixy="0" ixz="0" iyy="1" iyz="0" izz="1"/>
    </inertial>
  </link>
  <joint name="cobotta_pro_joint_5" type="revolute">
    <parent link="cobotta_pro_J4"/>
    <child link="cobotta_pro_J5"/>
    <origin rpy="0.000000 0.000000 0.000000" xyz="0.000000 0.030000 0.088000"/>
    <axis xyz="-0.000000 1.000000 -0.000000"/>
    <limit effort="1" lower="-2.61799387799149" upper="2.61799387799149" velocity="0.497418"/>
    <dynamics damping="0" friction="0"/>
  </joint>
  <link name="cobotta_pro_J6">
    <visual>
      <origin rpy="0 0 0" xyz="0 0 0"/>
      <geometry>
        <mesh filename="package://denso_robot_descriptions/robots/cvrb0609/meshes/J6.dae" scale="1 1 1"/>
      </geometry>
    </visual>
    <collision>
      <origin rpy="0 0 0" xyz="0 0 0"/>
      <geometry>
        <mesh filename="package://denso_robot_descriptions/robots/cvrb0609/meshes/J6.dae" scale="1 1 1"/>
      </geometry>
    </collision>
    <inertial>
      <mass value="1"/>
      <origin rpy="0.000000 0.000000 0.000000" xyz="0.000000 0.000000 0.000000"/>
      <inertia ixx="1" ixy="0" ixz="0" iyy="1" iyz="0" izz="1"/>
    </inertial>
  </link>
  <joint name="cobotta_pro_joint_6" type="revolute">
    <parent link="cobotta_pro_J5"/>
    <child link="cobotta_pro_J6"/>
    <origin rpy="0.000000 0.000000 0.000000" xyz="0.000000 0.120000 0.160000"/>
    <axis xyz="-0.000000 -0.000000 1.000000"/>
    <limit effort="1" lower="-6.28318530717959" upper="6.28318530717959" velocity="0.596903"/>
    <dynamics damping="0" friction="0"/>
  </joint>
  <ros2_control name="cobotta_pro_TopicBasedSystem" type="system">
    <hardware>
      <plugin>topic_based_ros2_control/TopicBasedSystem</plugin>
      <param name="joint_commands_topic">/topic_based_joint_commands</param>
      <param name="joint_states_topic">/topic_based_joint_states</param>
    </hardware>
    <joint name="cobotta_pro_joint_1">
      <command_interface name="position">
        <param name="min">-4.712389</param>
        <param name="max">4.712389</param>
      </command_interface>
      <command_interface name="acceleration">
        <param name="min">-0.310886</param>
        <param name="max">0.310886</param>
      </command_interface>
      <state_interface name="position"/>
      <state_interface name="velocity"/>
      <state_interface name="effort"/>
    </joint>
    <joint name="cobotta_pro_joint_2">
      <command_interface name="position">
        <param name="min">-2.617994</param>
        <param name="max">2.617994</param>
      </command_interface>
      <command_interface name="acceleration">
        <param name="min">-0.310886</param>
        <param name="max">0.310886</param>
      </command_interface>
      <state_interface name="position"/>
      <state_interface name="velocity"/>
      <state_interface name="effort"/>
    </joint>
    <joint name="cobotta_pro_joint_3">
      <command_interface name="position">
        <param name="min">-2.617994</param>
        <param name="max">2.617994</param>
      </command_interface>
      <command_interface name="acceleration">
        <param name="min">-0.621773</param>
        <param name="max">0.621773</param>
      </command_interface>
      <state_interface name="position"/>
      <state_interface name="velocity"/>
      <state_interface name="effort"/>
    </joint>
    <joint name="cobotta_pro_joint_4">
      <command_interface name="position">
        <param name="min">-4.712389</param>
        <param name="max">4.712389</param>
      </command_interface>
      <command_interface name="acceleration">
        <param name="min">-0.049741</param>
        <param name="max">0.049741</param>
      </command_interface>
      <state_interface name="position"/>
      <state_interface name="velocity"/>
      <state_interface name="effort"/>
    </joint>
    <joint name="cobotta_pro_joint_5">
      <command_interface name="position">
        <param name="min">-2.617994</param>
        <param name="max">2.617994</param>
      </command_interface>
      <command_interface name="acceleration">
        <param name="min">-0.690860</param>
        <param name="max">0.690860</param>
      </command_interface>
      <state_interface name="position"/>
      <state_interface name="velocity"/>
      <state_interface name="effort"/>
    </joint>
    <joint name="cobotta_pro_joint_6">
      <command_interface name="position">
        <param name="min">-6.283185</param>
        <param name="max">6.283185</param>
      </command_interface>
      <command_interface name="acceleration">
        <param name="min">-0.690860</param>
        <param name="max">0.690860</param>
      </command_interface>
      <state_interface name="position"/>
      <state_interface name="velocity"/>
      <state_interface name="effort"/>
    </joint>
  </ros2_control>
  <link name="world"/>
  <!-- base_plate link to cobotta link -->
  <joint name="joint_w" type="fixed">
    <origin rpy="0 0 1.5708" xyz="0 0 0"/>
    <parent link="robot_base_plate_link"/>
    <child link="cobotta_pro_base_link"/>
  </joint>
  <joint name="world_cell_joint" type="fixed">
    <parent link="world"/>
    <child link="cell_link"/>
    <origin rpy="0 0 0" xyz="0 0 0"/>
  </joint>
  <link name="cell_link">
    <inertial>
      <origin rpy="0 0 0" xyz="-0.010188 0.010903 0.93146"/>
      <mass value="1383.8"/>
      <inertia ixx="833.74" ixy="-0.082289" ixz="0.013641" iyy="819.21" iyz="0.033946" izz="522.69"/>
    </inertial>
    <visual>
      <origin rpy="0 0 0" xyz="0 0 0"/>
      <geometry>
        <mesh filename="package://techtory_cell_description/urdf/mesh/cell_link.STL"/>
      </geometry>
      <material name="">
        <color rgba="0.85098 0.72157 0.72157 1"/>
      </material>
    </visual>
    <collision>
      <origin rpy="0 0 0" xyz="0 0 0"/>
      <geometry>
        <mesh filename="package://techtory_cell_description/urdf/mesh/cell_link.STL"/>
      </geometry>
    </collision>
  </link>
  <link name="robot_base_plate_link">
    <inertial>
      <origin rpy="0 0 0" xyz="-0.010188 0.010903 0.93146"/>
      <mass value="1383.8"/>
      <inertia ixx="833.74" ixy="-0.082289" ixz="0.013641" iyy="819.21" iyz="0.033946" izz="522.69"/>
    </inertial>
    <visual>
      <origin rpy="0 0 0" xyz="0 0 0"/>
      <geometry>
        <mesh filename="package://techtory_cell_description/urdf/mesh/robot_base_link.STL" scale="1 1 1"/>
      </geometry>
      <material name="">
        <color rgba="0.85098 0.72157 0.72157 1"/>
      </material>
    </visual>
    <collision>
      <origin rpy="0 0 0" xyz="0 0 0"/>
      <geometry>
        <mesh filename="package://techtory_cell_description/urdf/mesh/robot_base_link.STL" scale="1 1 1"/>
      </geometry>
    </collision>
  </link>
  <joint name="robot_base_plate_link_joint" type="fixed">
    <parent link="cell_link"/>
    <child link="robot_base_plate_link"/>
    <origin rpy="0 0 0" xyz="-0.275 -0.24 0.94"/>
  </joint>
  <link name="rg6_base_link">
    <inertial>
      <origin rpy="0 0 0" xyz="0.0 0.0 0.0"/>
      <mass value="0.7"/>
      <inertia ixx="1.0E-03" ixy="1.0E-06" ixz="1.0E-06" iyy="1.0E-03" iyz="1.0E-06" izz="1.0E-03"/>
    </inertial>
    <visual>
      <origin rpy="0 0 0" xyz="0 0 0"/>
      <geometry>
        <mesh filename="package://onrobot_rg_description/meshes/rg6/visual/base_link.stl"/>
      </geometry>
      <material name="">
        <color rgba="0.8 0.8 0.8 1"/>
      </material>
    </visual>
    <collision>
      <origin rpy="0 0 0" xyz="0 0 0"/>
      <geometry>
        <mesh filename="package://onrobot_rg_description/meshes/rg6/collision/base_link.stl"/>
      </geometry>
    </collision>
  </link>
  <gazebo reference="rg6_base_link">
    <mu1>1.0</mu1>
    <mu2>1.0</mu2>
    <selfCollide>false</selfCollide>
    <material>Gazebo/White</material>
  </gazebo>
  <link name="rg6_left_outer_knuckle">
    <inertial>
      <origin rpy="0 0 0" xyz="0.0 0.0 0.0"/>
      <mass value="0.05"/>
      <inertia ixx="1.0E-03" ixy="1.0E-06" ixz="1.0E-06" iyy="1.0E-03" iyz="1.0E-06" izz="1.0E-03"/>
    </inertial>
    <visual>
      <origin rpy="0 0 0" xyz="0 0 0"/>
      <geometry>
        <mesh filename="package://onrobot_rg_description/meshes/rg6/visual/outer_knuckle.stl"/>
      </geometry>
      <material name="">
        <color rgba="0.8 0.8 0.8 1"/>
      </material>
    </visual>
    <collision>
      <origin rpy="0 0 0" xyz="0 0 0"/>
      <geometry>
        <mesh filename="package://onrobot_rg_description/meshes/rg6/collision/outer_knuckle.stl"/>
      </geometry>
    </collision>
  </link>
  <gazebo reference="rg6_left_outer_knuckle">
    <mu1>1.0</mu1>
    <mu2>1.0</mu2>
    <selfCollide>false</selfCollide>
    <material>Gazebo/White</material>
  </gazebo>
  <link name="rg6_left_inner_knuckle">
    <inertial>
      <origin rpy="0 0 0" xyz="0.0 0.0 0.0"/>
      <mass value="0.05"/>
      <inertia ixx="1.0E-03" ixy="1.0E-06" ixz="1.0E-06" iyy="1.0E-03" iyz="1.0E-06" izz="1.0E-03"/>
    </inertial>
    <visual>
      <origin rpy="0 0 0" xyz="0 0 0"/>
      <geometry>
        <mesh filename="package://onrobot_rg_description/meshes/rg6/visual/inner_knuckle.stl"/>
      </geometry>
      <material name="">
        <color rgba="0.8 0.8 0.8 1"/>
      </material>
    </visual>
    <collision>
      <origin rpy="0 0 0" xyz="0 0 0"/>
      <geometry>
        <mesh filename="package://onrobot_rg_description/meshes/rg6/collision/inner_knuckle.stl"/>
      </geometry>
    </collision>
  </link>
  <gazebo reference="rg6_left_inner_knuckle">
    <mu1>1.0</mu1>
    <mu2>1.0</mu2>
    <selfCollide>false</selfCollide>
    <material>Gazebo/White</material>
  </gazebo>
  <link name="rg6_left_inner_finger">
    <inertial>
      <origin rpy="0 0 0" xyz="0.0 0.0 0.0"/>
      <mass value="0.05"/>
      <inertia ixx="1.0E-03" ixy="1.0E-06" ixz="1.0E-06" iyy="1.0E-03" iyz="1.0E-06" izz="1.0E-03"/>
    </inertial>
    <visual>
      <origin rpy="0 0 0" xyz="0 0 0"/>
      <geometry>
        <mesh filename="package://onrobot_rg_description/meshes/rg6/visual/inner_finger.stl"/>
      </geometry>
      <material name="">
        <color rgba="0.1 0.1 0.1 1"/>
      </material>
    </visual>
    <collision>
      <origin rpy="0 0 0" xyz="0 0 0"/>
      <geometry>
        <mesh filename="package://onrobot_rg_description/meshes/rg6/collision/inner_finger.stl"/>
      </geometry>
    </collision>
  </link>
  <gazebo reference="rg6_left_inner_finger">
    <kp>1000000.0</kp>
    <kd>1.0</kd>
    <mu1>1.0</mu1>
    <mu2>1.0</mu2>
    <minDepth>0.001</minDepth>
    <selfCollide>false</selfCollide>
    <material>Gazebo/Black</material>
  </gazebo>
  <link name="rg6_right_outer_knuckle">
    <inertial>
      <origin rpy="0 0 0" xyz="0.0 0.0 0.0"/>
      <mass value="0.05"/>
      <inertia ixx="1.0E-03" ixy="1.0E-06" ixz="1.0E-06" iyy="1.0E-03" iyz="1.0E-06" izz="1.0E-03"/>
    </inertial>
    <visual>
      <origin rpy="0 0 0" xyz="0 0 0"/>
      <geometry>
        <mesh filename="package://onrobot_rg_description/meshes/rg6/visual/outer_knuckle.stl"/>
      </geometry>
      <material name="">
        <color rgba="0.8 0.8 0.8 1"/>
      </material>
    </visual>
    <collision>
      <origin rpy="0 0 0" xyz="0 0 0"/>
      <geometry>
        <mesh filename="package://onrobot_rg_description/meshes/rg6/collision/outer_knuckle.stl"/>
      </geometry>
    </collision>
  </link>
  <gazebo reference="rg6_right_outer_knuckle">
    <mu1>1.0</mu1>
    <mu2>1.0</mu2>
    <selfCollide>false</selfCollide>
    <material>Gazebo/White</material>
  </gazebo>
  <link name="rg6_right_inner_knuckle">
    <inertial>
      <origin rpy="0 0 0" xyz="0.0 0.0 0.0"/>
      <mass value="0.05"/>
      <inertia ixx="1.0E-03" ixy="1.0E-06" ixz="1.0E-06" iyy="1.0E-03" iyz="1.0E-06" izz="1.0E-03"/>
    </inertial>
    <visual>
      <origin rpy="0 0 0" xyz="0 0 0"/>
      <geometry>
        <mesh filename="package://onrobot_rg_description/meshes/rg6/visual/inner_knuckle.stl"/>
      </geometry>
      <material name="">
        <color rgba="0.8 0.8 0.8 1"/>
      </material>
    </visual>
    <collision>
      <origin rpy="0 0 0" xyz="0 0 0"/>
      <geometry>
        <mesh filename="package://onrobot_rg_description/meshes/rg6/collision/inner_knuckle.stl"/>
      </geometry>
    </collision>
  </link>
  <gazebo reference="rg6_right_inner_knuckle">
    <mu1>1.0</mu1>
    <mu2>1.0</mu2>
    <selfCollide>false</selfCollide>
    <material>Gazebo/White</material>
  </gazebo>
  <link name="rg6_right_inner_finger">
    <inertial>
      <origin rpy="0 0 0" xyz="0.0 0.0 0.0"/>
      <mass value="0.05"/>
      <inertia ixx="1.0E-03" ixy="1.0E-06" ixz="1.0E-06" iyy="1.0E-03" iyz="1.0E-06" izz="1.0E-03"/>
    </inertial>
    <visual>
      <origin rpy="0 0 0" xyz="0 0 0"/>
      <geometry>
        <mesh filename="package://onrobot_rg_description/meshes/rg6/visual/inner_finger.stl"/>
      </geometry>
      <material name="">
        <color rgba="0.1 0.1 0.1 1"/>
      </material>
    </visual>
    <collision>
      <origin rpy="0 0 0" xyz="0 0 0"/>
      <geometry>
        <mesh filename="package://onrobot_rg_description/meshes/rg6/collision/inner_finger.stl"/>
      </geometry>
    </collision>
  </link>
  <gazebo reference="rg6_right_inner_finger">
    <kp>1000000.0</kp>
    <kd>1.0</kd>
    <mu1>1.0</mu1>
    <mu2>1.0</mu2>
    <minDepth>0.001</minDepth>
    <selfCollide>false</selfCollide>
    <material>Gazebo/Black</material>
  </gazebo>
  <joint name="rg6_finger_joint" type="revolute">
    <origin rpy="0 0 0" xyz="0 -0.024112 0.136813"/>
    <parent link="rg6_base_link"/>
    <child link="rg6_left_outer_knuckle"/>
    <axis xyz="-1 0 0"/>
    <limit effort="1000" lower="-0.628319" upper="0.628319" velocity="2.0"/>
  </joint>
  <joint name="rg6_left_inner_knuckle_joint" type="revolute">
    <origin rpy="0 0 0.0" xyz="0 -0.01272 0.159500"/>
    <parent link="rg6_base_link"/>
    <child link="rg6_left_inner_knuckle"/>
    <axis xyz="1 0 0"/>
    <limit effort="1000" lower="-0.628319" upper="0.628319" velocity="2.0"/>
    <mimic joint="rg6_finger_joint" multiplier="-1" offset="0"/>
  </joint>
  <joint name="rg6_left_inner_finger_joint" type="revolute">
    <origin rpy="0 0 0" xyz="0 -0.047334999999999995 0.064495"/>
    <parent link="rg6_left_outer_knuckle"/>
    <child link="rg6_left_inner_finger"/>
    <axis xyz="1 0 0"/>
    <limit effort="1000" lower="-0.872665" upper="0.872665" velocity="2.0"/>
    <mimic joint="rg6_finger_joint" multiplier="1" offset="0"/>
  </joint>
  <joint name="rg6_right_outer_knuckle_joint" type="revolute">
    <origin rpy="0 0 3.141592653589793" xyz="0 0.024112 0.136813"/>
    <parent link="rg6_base_link"/>
    <child link="rg6_right_outer_knuckle"/>
    <axis xyz="1 0 0"/>
    <limit effort="1000" lower="-0.628319" upper="0.628319" velocity="2.0"/>
    <mimic joint="rg6_finger_joint" multiplier="-1" offset="0"/>
  </joint>
  <joint name="rg6_right_inner_knuckle_joint" type="revolute">
    <origin rpy="0 0 -3.141592653589793" xyz="0 0.01272 0.159500"/>
    <parent link="rg6_base_link"/>
    <child link="rg6_right_inner_knuckle"/>
    <axis xyz="1 0 0"/>
    <limit effort="1000" lower="-0.628319" upper="0.628319" velocity="2.0"/>
    <mimic joint="rg6_finger_joint" multiplier="-1" offset="0"/>
  </joint>
  <joint name="rg6_right_inner_finger_joint" type="revolute">
    <origin rpy="0 0 0" xyz="0 -0.047334999999999995 0.064495"/>
    <parent link="rg6_right_outer_knuckle"/>
    <child link="rg6_right_inner_finger"/>
    <axis xyz="1 0 0"/>
    <limit effort="1000" lower="-0.872665" upper="0.872665" velocity="2.0"/>
    <mimic joint="rg6_finger_joint" multiplier="1" offset="0"/>
  </joint>
  <transmission name="rg6_finger_joint_trans">
    <type>transmission_interface/SimpleTransmission</type>
    <joint name="rg6_finger_joint">
      <hardwareInterface>hardware_interface/EffortJointInterface</hardwareInterface>
    </joint>
    <actuator name="rg6_finger_joint_motor">
      <hardwareInterface>hardware_interface/EffortJointInterface</hardwareInterface>
      <mechanicalReduction>1</mechanicalReduction>
    </actuator>
  </transmission>
  <gazebo>
    <plugin filename="libgazebo_ros2_control.so" name="gazebo_ros2_control">
      <robotNamespace>/onrobot_rg6</robotNamespace>
      <robotSimType>gazebo_ros2_control/DefaultRobotHWSim</robotSimType>
    </plugin>
  </gazebo>
  <gazebo>
    <plugin filename="libroboticsgroup_upatras_gazebo_mimic_joint_plugin.so" name="mimic_left_inner_knuckle_joint">
      <joint>finger_joint</joint>
      <mimicJoint>left_inner_knuckle_joint</mimicJoint>
      <multiplier>1.0</multiplier>
      <offset>0.0</offset>
      <maxEffort>5.0</maxEffort>
      <!-- <hasPID /> -->
    </plugin>
    <plugin filename="libroboticsgroup_upatras_gazebo_mimic_joint_plugin.so" name="mimic_right_inner_knuckle_joint">
      <joint>finger_joint</joint>
      <mimicJoint>right_inner_knuckle_joint</mimicJoint>
      <multiplier>1.0</multiplier>
      <offset>0.0</offset>
      <maxEffort>5.0</maxEffort>
      <!-- <hasPID /> -->
    </plugin>
    <plugin filename="libroboticsgroup_upatras_gazebo_mimic_joint_plugin.so" name="mimic_left_inner_finger_joint">
      <joint>finger_joint</joint>
      <mimicJoint>left_inner_finger_joint</mimicJoint>
      <multiplier>-1.0</multiplier>
      <offset>0.0</offset>
      <maxEffort>5.0</maxEffort>
      <!-- <hasPID /> -->
    </plugin>
    <plugin filename="libroboticsgroup_upatras_gazebo_mimic_joint_plugin.so" name="mimic_right_inner_finger_joint">
      <joint>finger_joint</joint>
      <mimicJoint>right_inner_finger_joint</mimicJoint>
      <multiplier>-1.0</multiplier>
      <offset>0.0</offset>
      <maxEffort>5.0</maxEffort>
      <!-- <hasPID /> -->
    </plugin>
    <plugin filename="libroboticsgroup_upatras_gazebo_mimic_joint_plugin.so" name="mimic_right_outer_knuckle_joint">
      <joint>finger_joint</joint>
      <mimicJoint>right_outer_knuckle_joint</mimicJoint>
      <multiplier>1.0</multiplier>
      <offset>0.0</offset>
      <maxEffort>5.0</maxEffort>
      <!-- <hasPID /> -->
    </plugin>
  </gazebo>
  <!-- Fixed joint from cobottaJ6 to rg6_baselink -->
  <joint name="joint_rg6" type="fixed">
    <origin rpy="0 0 0" xyz="0 0 0"/>
    <parent link="cobotta_pro_J6"/>
    <child link="rg6_base_link"/>
  </joint>
  <!-- virtual end-effector link for cobotta_proJ6 -->
  <link name="cobotta_pro_tool0"/>
  <joint name="cobotta_pro_tool0_joint" type="fixed">
    <parent link="rg6_base_link"/>
    <child link="cobotta_pro_tool0"/>
    <origin rpy="0 0 0" xyz="0 0 0.25"/>
  </joint>
  <!-- virtual end-effector link for cobotta_proJ6 -->
</robot>
