<?xml version="1.0" ?>
<!-- =================================================================================== -->
<!-- |    This document was autogenerated by xacro from techtory_cvrb0609_workcell.urdf.xacro | -->
<!-- |    EDITING THIS FILE BY HAND IS NOT RECOMMENDED                                 | -->
<!-- =================================================================================== -->
<robot name="techtory_demo_description">
  <link name="world"/>
  <!--
    Base Denso robot xacro macro.

    NOTE this is NOT a URDF. It cannot directly be loaded by consumers
    expecting a flattened '.urdf' file. See the top-level '.xacro' for that
    (but note that .xacro must still be processed by the xacro command).

    This file models the base kinematic chain of a Denso robot.

    Author DENSO WAVE INCORPORATED
  -->
  <!--
    NOTE the macro defined in this file is NOT part of the public API of this
          package. Users CANNOT rely on this file being available, or stored in
          this location. Nor can they rely on the existence of the macro.
  -->
  <link name="cobotta_pro_base_link">
    <visual>
      <origin rpy="0 0 0" xyz="0 0 0"/>
      <geometry>
        <mesh filename="package://cvrb0609_description/meshes//base_link.dae" scale="1 1 1"/>
      </geometry>
    </visual>
    <collision>
      <origin rpy="0 0 0" xyz="0 0 0"/>
      <geometry>
        <mesh filename="package://cvrb0609_description/meshes//base_link.dae" scale="1 1 1"/>
      </geometry>
    </collision>
    <inertial>
      <mass value="1"/>
      <origin rpy="0.000000 0.000000 0.000000" xyz="0.000000 0.000000 0.000000"/>
      <inertia ixx="1" ixy="0" ixz="0" iyy="1" iyz="0" izz="1"/>
    </inertial>
  </link>
  <link name="cobotta_pro_J1">
    <visual>
      <origin rpy="0 0 0" xyz="0 0 0"/>
      <geometry>
        <mesh filename="package://cvrb0609_description/meshes//J1.dae" scale="1 1 1"/>
      </geometry>
    </visual>
    <collision>
      <origin rpy="0 0 0" xyz="0 0 0"/>
      <geometry>
        <mesh filename="package://cvrb0609_description/meshes//J1.dae" scale="1 1 1"/>
      </geometry>
    </collision>
    <inertial>
      <mass value="1"/>
      <origin rpy="0.000000 0.000000 0.000000" xyz="0.000000 0.000000 0.000000"/>
      <inertia ixx="1" ixy="0" ixz="0" iyy="1" iyz="0" izz="1"/>
    </inertial>
  </link>
  <joint name="cobotta_pro_joint_1" type="revolute">
    <parent link="cobotta_pro_base_link"/>
    <child link="cobotta_pro_J1"/>
    <origin rpy="0.000000 0.000000 0.000000" xyz="0.000000 0.000000 0.101000"/>
    <axis xyz="-0.000000 -0.000000 1.000000"/>
    <limit effort="1" lower="-4.71238898038469" upper="4.71238898038469" velocity="0.397935"/>
    <dynamics damping="0" friction="0"/>
  </joint>
  <link name="cobotta_pro_J2">
    <visual>
      <origin rpy="0 0 0" xyz="0 0 0"/>
      <geometry>
        <mesh filename="package://cvrb0609_description/meshes//J2.dae" scale="1 1 1"/>
      </geometry>
    </visual>
    <collision>
      <origin rpy="0 0 0" xyz="0 0 0"/>
      <geometry>
        <mesh filename="package://cvrb0609_description/meshes//J2.dae" scale="1 1 1"/>
      </geometry>
    </collision>
    <inertial>
      <mass value="1"/>
      <origin rpy="0.000000 0.000000 0.000000" xyz="0.000000 0.000000 0.000000"/>
      <inertia ixx="1" ixy="0" ixz="0" iyy="1" iyz="0" izz="1"/>
    </inertial>
  </link>
  <joint name="cobotta_pro_joint_2" type="revolute">
    <parent link="cobotta_pro_J1"/>
    <child link="cobotta_pro_J2"/>
    <origin rpy="0.000000 0.000000 0.000000" xyz="0.000000 0.000000 0.109000"/>
    <axis xyz="-0.000000 1.000000 -0.000000"/>
    <limit effort="1" lower="-2.61799387799149" upper="2.61799387799149" velocity="0.331612"/>
    <dynamics damping="0" friction="0"/>
  </joint>
  <link name="cobotta_pro_J3">
    <visual>
      <origin rpy="0 0 0" xyz="0 0 0"/>
      <geometry>
        <mesh filename="package://cvrb0609_description/meshes//J3.dae" scale="1 1 1"/>
      </geometry>
    </visual>
    <collision>
      <origin rpy="0 0 0" xyz="0 0 0"/>
      <geometry>
        <mesh filename="package://cvrb0609_description/meshes//J3.dae" scale="1 1 1"/>
      </geometry>
    </collision>
    <inertial>
      <mass value="1"/>
      <origin rpy="0.000000 0.000000 0.000000" xyz="0.000000 0.000000 0.000000"/>
      <inertia ixx="1" ixy="0" ixz="0" iyy="1" iyz="0" izz="1"/>
    </inertial>
  </link>
  <joint name="cobotta_pro_joint_3" type="revolute">
    <parent link="cobotta_pro_J2"/>
    <child link="cobotta_pro_J3"/>
    <origin rpy="0.000000 0.000000 0.000000" xyz="0.000000 0.000000 0.510000"/>
    <axis xyz="-0.000000 1.000000 -0.000000"/>
    <limit effort="1" lower="-2.61799387799149" upper="2.61799387799149" velocity="0.397935"/>
    <dynamics damping="0" friction="0"/>
  </joint>
  <link name="cobotta_pro_J4">
    <visual>
      <origin rpy="0 0 0" xyz="0 0 0"/>
      <geometry>
        <mesh filename="package://cvrb0609_description/meshes//J4.dae" scale="1 1 1"/>
      </geometry>
    </visual>
    <collision>
      <origin rpy="0 0 0" xyz="0 0 0"/>
      <geometry>
        <mesh filename="package://cvrb0609_description/meshes//J4.dae" scale="1 1 1"/>
      </geometry>
    </collision>
    <inertial>
      <mass value="1"/>
      <origin rpy="0.000000 0.000000 0.000000" xyz="0.000000 0.000000 0.000000"/>
      <inertia ixx="1" ixy="0" ixz="0" iyy="1" iyz="0" izz="1"/>
    </inertial>
  </link>
  <joint name="cobotta_pro_joint_4" type="revolute">
    <parent link="cobotta_pro_J3"/>
    <child link="cobotta_pro_J4"/>
    <origin rpy="0.000000 0.000000 0.000000" xyz="0.000000 -0.030000 0.302000"/>
    <axis xyz="-0.000000 -0.000000 1.000000"/>
    <limit effort="1" lower="-4.71238898038469" upper="4.71238898038469" velocity="0.497418"/>
    <dynamics damping="0" friction="0"/>
  </joint>
  <link name="cobotta_pro_J5">
    <visual>
      <origin rpy="0 0 0" xyz="0 0 0"/>
      <geometry>
        <mesh filename="package://cvrb0609_description/meshes//J5.dae" scale="1 1 1"/>
      </geometry>
    </visual>
    <collision>
      <origin rpy="0 0 0" xyz="0 0 0"/>
      <geometry>
        <mesh filename="package://cvrb0609_description/meshes//J5.dae" scale="1 1 1"/>
      </geometry>
    </collision>
    <inertial>
      <mass value="1"/>
      <origin rpy="0.000000 0.000000 0.000000" xyz="0.000000 0.000000 0.000000"/>
      <inertia ixx="1" ixy="0" ixz="0" iyy="1" iyz="0" izz="1"/>
    </inertial>
  </link>
  <joint name="cobotta_pro_joint_5" type="revolute">
    <parent link="cobotta_pro_J4"/>
    <child link="cobotta_pro_J5"/>
    <origin rpy="0.000000 0.000000 0.000000" xyz="0.000000 0.030000 0.088000"/>
    <axis xyz="-0.000000 1.000000 -0.000000"/>
    <limit effort="1" lower="-2.61799387799149" upper="2.61799387799149" velocity="0.497418"/>
    <dynamics damping="0" friction="0"/>
  </joint>
  <link name="cobotta_pro_J6">
    <visual>
      <origin rpy="0 0 0" xyz="0 0 0"/>
      <geometry>
        <mesh filename="package://cvrb0609_description/meshes//J6.dae" scale="1 1 1"/>
      </geometry>
    </visual>
    <collision>
      <origin rpy="0 0 0" xyz="0 0 0"/>
      <geometry>
        <mesh filename="package://cvrb0609_description/meshes//J6.dae" scale="1 1 1"/>
      </geometry>
    </collision>
    <inertial>
      <mass value="1"/>
      <origin rpy="0.000000 0.000000 0.000000" xyz="0.000000 0.000000 0.000000"/>
      <inertia ixx="1" ixy="0" ixz="0" iyy="1" iyz="0" izz="1"/>
    </inertial>
  </link>
  <joint name="cobotta_pro_joint_6" type="revolute">
    <parent link="cobotta_pro_J5"/>
    <child link="cobotta_pro_J6"/>
    <origin rpy="0.000000 0.000000 0.000000" xyz="0.000000 0.120000 0.160000"/>
    <axis xyz="-0.000000 -0.000000 1.000000"/>
    <limit effort="1" lower="-6.28318530717959" upper="6.28318530717959" velocity="0.596903"/>
    <dynamics damping="0" friction="0"/>
  </joint>
  <!-- Instantiate Schmalz_ecbpmi Gripper -->
  <!-- Specify some standard inertial calculations https://en.wikipedia.org/wiki/List_of_moments_of_inertia -->
  <!-- These make use of xacro's mathematical functionality -->
  <material name="blue">
    <color rgba="0 0.2 1 1"/>
  </material>
  <material name="green">
    <color rgba="0 0.9 0.3 1"/>
  </material>
  <material name="white">
    <color rgba="1 1 1 1"/>
  </material>
  <!--Base Link-->
  <link name="schmalz_ecbpmi_base_link">
    <visual>
      <geometry>
        <cylinder length="0.037" radius="0.0155"/>
      </geometry>
      <material name="blue"/>
      <origin rpy="0 0 0" xyz="0 0 0.0185"/>
    </visual>
    <collision>
      <geometry>
        <cylinder length="0.037" radius="0.0155"/>
      </geometry>
      <origin rpy="0 0 0" xyz="0 0 0.0185"/>
    </collision>
    <inertial>
      <origin rpy="0 0 0" xyz="0 0 0.0185"/>
      <mass value="0.1"/>
      <inertia ixx="1.741458333333333e-05" ixy="0.0" ixz="0.0" iyy="1.741458333333333e-05" iyz="0.0" izz="1.20125e-05"/>
    </inertial>
  </link>
  <!--Main gripper-->
  <link name="schmalz_ecbpmi_body_link">
    <visual>
      <geometry>
        <mesh filename="package://cvrb0609_description/meshes/Schmalz_ECBPMi.stl" scale="1 1 1"/>
      </geometry>
      <origin rpy="-1.5707963267948966 0 0" xyz="0 0 0.0185"/>
      <material name="green"/>
    </visual>
    <collision>
      <geometry>
        <mesh filename="package://cvrb0609_description/meshes/Schmalz_ECBPMi.stl" scale="1 1 1"/>
      </geometry>
      <origin rpy="-1.5707963267948966 0 0" xyz="0 0 0.0185"/>
    </collision>
    <inertial>
      <origin rpy="1.5707963267948966 0 0" xyz="0 0 0.0185"/>
      <mass value="0.224"/>
      <inertia ixx="0.00015888618666666664" ixy="0.0" ixz="0.0" iyy="0.00015888618666666664" iyz="0.0" izz="0.000148176"/>
    </inertial>
  </link>
  <!-- Virtual link for visualizytion and planning-->
  <link name="tool_tip"/>
  <!-- Joints-->
  <joint name="schmalz_ecbpmi_body_joint" type="fixed">
    <parent link="schmalz_ecbpmi_base_link"/>
    <child link="schmalz_ecbpmi_body_link"/>
    <origin rpy="0.0 0.0 0.0" xyz="0.0 0.0 0.052199999999999996"/>
  </joint>
  <joint name="schmalz_ecbpmi_tip_joint" type="fixed">
    <parent link="schmalz_ecbpmi_base_link"/>
    <child link="tool_tip"/>
    <origin rpy="0.0 0.0 0.0" xyz="0 0 0.1004"/>
  </joint>
  <joint name="schmalz_ecbpmi_cup_joint" type="fixed">
    <parent link="cobotta_pro_J6"/>
    <child link="schmalz_ecbpmi_base_link"/>
    <origin rpy="0 0 0" xyz="0 0 0"/>
  </joint>
  <!-- base_plate link to cobotta link -->
  <joint name="joint_w" type="fixed">
    <origin rpy="0 0 0" xyz="0 0 0"/>
    <parent link="robot_base_plate_link"/>
    <child link="cobotta_pro_base_link"/>
  </joint>
  <joint name="world_cell_joint" type="fixed">
    <parent link="world"/>
    <child link="cell_link"/>
    <origin rpy="0 0 0" xyz="0 0 0"/>
  </joint>
  <link name="cell_link">
    <inertial>
      <origin rpy="0 0 0" xyz="-0.010188 0.010903 0.93146"/>
      <mass value="1383.8"/>
      <inertia ixx="833.74" ixy="-0.082289" ixz="0.013641" iyy="819.21" iyz="0.033946" izz="522.69"/>
    </inertial>
    <visual>
      <origin rpy="0 0 0" xyz="0 0 0"/>
      <geometry>
        <mesh filename="package://techtory_cell_description/urdf/mesh/cell_link.STL"/>
      </geometry>
      <material name="">
        <color rgba="0.85098 0.72157 0.72157 1"/>
      </material>
    </visual>
    <collision>
      <origin rpy="0 0 0" xyz="0 0 0"/>
      <geometry>
        <mesh filename="package://techtory_cell_description/urdf/mesh/cell_link.STL"/>
      </geometry>
    </collision>
  </link>
  <link name="robot_base_plate_link">
    <inertial>
      <origin rpy="0 0 0" xyz="-0.010188 0.010903 0.93146"/>
      <mass value="1383.8"/>
      <inertia ixx="833.74" ixy="-0.082289" ixz="0.013641" iyy="819.21" iyz="0.033946" izz="522.69"/>
    </inertial>
    <visual>
      <origin rpy="0 0 0" xyz="0 0 0"/>
      <geometry>
        <mesh filename="package://techtory_cell_description/urdf/mesh/robot_base_link.STL" scale="0.9 0.9 1.5"/>
      </geometry>
      <material name="">
        <color rgba="0.85098 0.72157 0.72157 1"/>
      </material>
    </visual>
    <collision>
      <origin rpy="0 0 0" xyz="0 0 0"/>
      <geometry>
        <mesh filename="package://techtory_cell_description/urdf/mesh/robot_base_link.STL" scale="0.9 0.9 1.5"/>
      </geometry>
    </collision>
  </link>
  <joint name="robot_base_plate_link_joint" type="fixed">
    <parent link="cell_link"/>
    <child link="robot_base_plate_link"/>
    <origin rpy="0 0 0" xyz="0 -0.3 0.93"/>
  </joint>
  <actuator>
    <position name="cobotta_pro_joint_1" joint="cobotta_pro_joint_1" kp="1000.0" kd="100.0" dampratio="0.1" ctrlrange="-4.71239 4.71239"/>
    <position name="cobotta_pro_joint_2" joint="cobotta_pro_joint_2" kp="1000.0" kd="100.0" dampratio="0.1" ctrlrange="-2.61799 2.61799"/>
    <position name="cobotta_pro_joint_3" joint="cobotta_pro_joint_3" kp="1000.0" kd="100.0" dampratio="0.1" ctrlrange="-2.61799 2.61799"/>
    <position name="cobotta_pro_joint_4" joint="cobotta_pro_joint_4" kp="1000.0" kd="100.0" dampratio="0.1" ctrlrange="-4.71239 4.71239"/>
    <position name="cobotta_pro_joint_5" joint="cobotta_pro_joint_5" kp="1000.0" kd="100.0" dampratio="0.1" ctrlrange="-2.61799 2.61799"/>
    <position name="cobotta_pro_joint_6" joint="cobotta_pro_joint_6" kp="1000.0" kd="100.0" dampratio="0.1" ctrlrange="-6.28319 6.28319"/>
  </actuator>
  <ros2_control name="FakeSystem" type="system">
    <hardware>
      <!-- By default, set up controllers for simulation. This won't work on real hardware -->
      <plugin>mock_components/GenericSystem</plugin>
      <!-- <plugin>topic_based_ros2_control/TopicBasedSystem</plugin>
      <plugin name="joint_command_topic">/isaac_joint_command</plugin>
      <plugin name="joint_state_topic">/isaac_joint_states</plugin> -->
    </hardware>
    <joint name="cobotta_pro_joint_1">
      <command_interface name="position"/>
      <state_interface name="position">
        <param name="initial_value">-0.942</param>
      </state_interface>
      <state_interface name="velocity"/>
    </joint>
    <joint name="cobotta_pro_joint_2">
      <command_interface name="position"/>
      <state_interface name="position">
        <param name="initial_value">0</param>
      </state_interface>
      <state_interface name="velocity"/>
    </joint>
    <joint name="cobotta_pro_joint_3">
      <command_interface name="position"/>
      <state_interface name="position">
        <param name="initial_value">-1.571</param>
      </state_interface>
      <state_interface name="velocity"/>
    </joint>
    <joint name="cobotta_pro_joint_4">
      <command_interface name="position"/>
      <state_interface name="position">
        <param name="initial_value">-3.031</param>
      </state_interface>
      <state_interface name="velocity"/>
    </joint>
    <joint name="cobotta_pro_joint_5">
      <command_interface name="position"/>
      <state_interface name="position">
        <param name="initial_value">1.543</param>
      </state_interface>
      <state_interface name="velocity"/>
    </joint>
    <joint name="cobotta_pro_joint_6">
      <command_interface name="position"/>
      <state_interface name="position">
        <param name="initial_value">0.102</param>
      </state_interface>
      <state_interface name="velocity"/>
    </joint>
  </ros2_control>
</robot>
