<?xml version="1.0" ?>
<!-- =================================================================================== -->
<!-- |    This document was autogenerated by xacro from techtory_cobotta_workcell.urdf.xacro | -->
<!-- |    EDITING THIS FILE BY HAND IS NOT RECOMMENDED                                 | -->
<!-- =================================================================================== -->
<robot name="techtory_demo_description">
  <!--
    Base Denso robot xacro macro.

    NOTE this is NOT a URDF. It cannot directly be loaded by consumers
    expecting a flattened '.urdf' file. See the top-level '.xacro' for that
    (but note that .xacro must still be processed by the xacro command).

    This file models the base kinematic chain of a Denso robot.

    Author DENSO WAVE INCORPORATED
  -->
  <!--
    NOTE the macro defined in this file is NOT part of the public API of this
          package. Users CANNOT rely on this file being available, or stored in
          this location. Nor can they rely on the existence of the macro.
  -->
  <!-- <xacro:if value="${sim}">
      <gazebo>
        <plugin filename="libgazebo_ros2_control.so" name="gazebo_ros2_control">
          <parameters>$(find denso_robot_moveit_config)/robots/$(arg model)/config/denso_robot_controllers.yaml</parameters>
        </plugin>
      </gazebo>
      <xacro:gazebo_ros2_control name="CobottaSystem" namespace="$(arg namespace)"/>
    </xacro:if>

    <xacro:if value="${use_mock_hardware}">
      <xacro:mock_ros2_control name="GenericSystem" namespace="$(arg namespace)"/>
    </xacro:if> -->
  <!-- 
    <xacro:if value="${sim}">
      <xacro:topic_based_ros2_control name="CobottaSystem" namespace="$(arg namespace)"/>
    </xacro:if>
    <xacro:unless value="${sim}">
      <xacro:if value="${use_mock_hardware}">
        <xacro:mock_ros2_control name="GenericSystem" namespace="$(arg namespace)"/>
      </xacro:if>
    </xacro:unless> -->
  <!-- ros2 control instance -->
  <!-- <xacro:unless value="${sim}">
      <xacro:unless value="${use_mock_hardware}">
        <xacro:denso_robot_ros2_control
          name="CobottaSystem"
          namespace="$(arg namespace)"
          sim="$(arg sim)"
          model="$(arg model)"
          ip_address="$(arg ip_address)"
          robot_name="$(arg robot_name)"
          robot_joints="$(arg robot_joints)"
          joint_1="$(arg joint_1)"
          joint_2="$(arg joint_2)"
          joint_3="$(arg joint_3)"
          joint_4="$(arg joint_4)"
          joint_5="$(arg joint_5)"
          joint_6="$(arg joint_6)"
          arm_group="$(arg arm_group)"
          controller_type="$(arg controller_type)"
          verbose="$(arg verbose)"
          send_format="$(arg send_format)"
          recv_format="$(arg recv_format)"
          use_mock_hardware="$(arg use_mock_hardware)"
        />
      </xacro:unless>
    </xacro:unless> -->
  <transmission name="cobotta_pro_trans_1">
    <type>transmission_interface/SimpleTransmission</type>
    <joint name="cobotta_pro_joint_1">
      <hardwareInterface></hardwareInterface>
    </joint>
    <actuator name="cobotta_pro_motor_1">
      <mechanicalReduction>1</mechanicalReduction>
    </actuator>
  </transmission>
  <transmission name="cobotta_pro_trans_2">
    <type>transmission_interface/SimpleTransmission</type>
    <joint name="cobotta_pro_joint_2">
      <hardwareInterface></hardwareInterface>
    </joint>
    <actuator name="cobotta_pro_motor_2">
      <mechanicalReduction>1</mechanicalReduction>
    </actuator>
  </transmission>
  <transmission name="cobotta_pro_trans_3">
    <type>transmission_interface/SimpleTransmission</type>
    <joint name="cobotta_pro_joint_3">
      <hardwareInterface></hardwareInterface>
    </joint>
    <actuator name="cobotta_pro_motor_3">
      <mechanicalReduction>1</mechanicalReduction>
    </actuator>
  </transmission>
  <transmission name="cobotta_pro_trans_4">
    <type>transmission_interface/SimpleTransmission</type>
    <joint name="cobotta_pro_joint_4">
      <hardwareInterface></hardwareInterface>
    </joint>
    <actuator name="cobotta_pro_motor_4">
      <mechanicalReduction>1</mechanicalReduction>
    </actuator>
  </transmission>
  <transmission name="cobotta_pro_trans_5">
    <type>transmission_interface/SimpleTransmission</type>
    <joint name="cobotta_pro_joint_5">
      <hardwareInterface></hardwareInterface>
    </joint>
    <actuator name="cobotta_pro_motor_5">
      <mechanicalReduction>1</mechanicalReduction>
    </actuator>
  </transmission>
  <transmission name="cobotta_pro_trans_6">
    <type>transmission_interface/SimpleTransmission</type>
    <joint name="cobotta_pro_joint_6">
      <hardwareInterface></hardwareInterface>
    </joint>
    <actuator name="cobotta_pro_motor_6">
      <mechanicalReduction>1</mechanicalReduction>
    </actuator>
  </transmission>
  <!-- Placeholder for ros2_control transmission which don't yet exist -->
  <!-- <link name="world"/>
		<joint name="$(arg namespace)joint_w" type="fixed">
			<parent link="world"/>
			<child link="$(arg namespace)base_link"/>
		</joint> -->
  <link name="cobotta_pro_base_link">
    <visual>
      <origin rpy="0 0 0" xyz="0 0 0"/>
      <geometry>
        <mesh filename="package://denso_robot_descriptions/robots/cvrb0609/meshes/base_link.dae" scale="1 1 1"/>
      </geometry>
    </visual>
    <collision>
      <origin rpy="0 0 0" xyz="0 0 0"/>
      <geometry>
        <mesh filename="package://denso_robot_descriptions/robots/cvrb0609/meshes/base_link.dae" scale="1 1 1"/>
      </geometry>
    </collision>
    <inertial>
      <mass value="1"/>
      <origin rpy="0.000000 0.000000 0.000000" xyz="0.000000 0.000000 0.000000"/>
      <inertia ixx="1" ixy="0" ixz="0" iyy="1" iyz="0" izz="1"/>
    </inertial>
  </link>
  <link name="cobotta_pro_J1">
    <visual>
      <origin rpy="0 0 0" xyz="0 0 0"/>
      <geometry>
        <mesh filename="package://denso_robot_descriptions/robots/cvrb0609/meshes/J1.dae" scale="1 1 1"/>
      </geometry>
    </visual>
    <collision>
      <origin rpy="0 0 0" xyz="0 0 0"/>
      <geometry>
        <mesh filename="package://denso_robot_descriptions/robots/cvrb0609/meshes/J1.dae" scale="1 1 1"/>
      </geometry>
    </collision>
    <inertial>
      <mass value="1"/>
      <origin rpy="0.000000 0.000000 0.000000" xyz="0.000000 0.000000 0.000000"/>
      <inertia ixx="1" ixy="0" ixz="0" iyy="1" iyz="0" izz="1"/>
    </inertial>
  </link>
  <joint name="cobotta_pro_joint_1" type="revolute">
    <parent link="cobotta_pro_base_link"/>
    <child link="cobotta_pro_J1"/>
    <origin rpy="0.000000 0.000000 0.000000" xyz="0.000000 0.000000 0.101000"/>
    <axis xyz="-0.000000 -0.000000 1.000000"/>
    <limit effort="1" lower="-4.71238898038469" upper="4.71238898038469" velocity="0.397935"/>
    <dynamics damping="0" friction="0"/>
  </joint>
  <link name="cobotta_pro_J2">
    <visual>
      <origin rpy="0 0 0" xyz="0 0 0"/>
      <geometry>
        <mesh filename="package://denso_robot_descriptions/robots/cvrb0609/meshes/J2.dae" scale="1 1 1"/>
      </geometry>
    </visual>
    <collision>
      <origin rpy="0 0 0" xyz="0 0 0"/>
      <geometry>
        <mesh filename="package://denso_robot_descriptions/robots/cvrb0609/meshes/J2.dae" scale="1 1 1"/>
      </geometry>
    </collision>
    <inertial>
      <mass value="1"/>
      <origin rpy="0.000000 0.000000 0.000000" xyz="0.000000 0.000000 0.000000"/>
      <inertia ixx="1" ixy="0" ixz="0" iyy="1" iyz="0" izz="1"/>
    </inertial>
  </link>
  <joint name="cobotta_pro_joint_2" type="revolute">
    <parent link="cobotta_pro_J1"/>
    <child link="cobotta_pro_J2"/>
    <origin rpy="0.000000 0.000000 0.000000" xyz="0.000000 0.000000 0.109000"/>
    <axis xyz="-0.000000 1.000000 -0.000000"/>
    <limit effort="1" lower="-2.61799387799149" upper="2.61799387799149" velocity="0.331612"/>
    <dynamics damping="0" friction="0"/>
  </joint>
  <link name="cobotta_pro_J3">
    <visual>
      <origin rpy="0 0 0" xyz="0 0 0"/>
      <geometry>
        <mesh filename="package://denso_robot_descriptions/robots/cvrb0609/meshes/J3.dae" scale="1 1 1"/>
      </geometry>
    </visual>
    <collision>
      <origin rpy="0 0 0" xyz="0 0 0"/>
      <geometry>
        <mesh filename="package://denso_robot_descriptions/robots/cvrb0609/meshes/J3.dae" scale="1 1 1"/>
      </geometry>
    </collision>
    <inertial>
      <mass value="1"/>
      <origin rpy="0.000000 0.000000 0.000000" xyz="0.000000 0.000000 0.000000"/>
      <inertia ixx="1" ixy="0" ixz="0" iyy="1" iyz="0" izz="1"/>
    </inertial>
  </link>
  <joint name="cobotta_pro_joint_3" type="revolute">
    <parent link="cobotta_pro_J2"/>
    <child link="cobotta_pro_J3"/>
    <origin rpy="0.000000 0.000000 0.000000" xyz="0.000000 0.000000 0.510000"/>
    <axis xyz="-0.000000 1.000000 -0.000000"/>
    <limit effort="1" lower="-2.61799387799149" upper="2.61799387799149" velocity="0.397935"/>
    <dynamics damping="0" friction="0"/>
  </joint>
  <link name="cobotta_pro_J4">
    <visual>
      <origin rpy="0 0 0" xyz="0 0 0"/>
      <geometry>
        <mesh filename="package://denso_robot_descriptions/robots/cvrb0609/meshes/J4.dae" scale="1 1 1"/>
      </geometry>
    </visual>
    <collision>
      <origin rpy="0 0 0" xyz="0 0 0"/>
      <geometry>
        <mesh filename="package://denso_robot_descriptions/robots/cvrb0609/meshes/J4.dae" scale="1 1 1"/>
      </geometry>
    </collision>
    <inertial>
      <mass value="1"/>
      <origin rpy="0.000000 0.000000 0.000000" xyz="0.000000 0.000000 0.000000"/>
      <inertia ixx="1" ixy="0" ixz="0" iyy="1" iyz="0" izz="1"/>
    </inertial>
  </link>
  <joint name="cobotta_pro_joint_4" type="revolute">
    <parent link="cobotta_pro_J3"/>
    <child link="cobotta_pro_J4"/>
    <origin rpy="0.000000 0.000000 0.000000" xyz="0.000000 -0.030000 0.302000"/>
    <axis xyz="-0.000000 -0.000000 1.000000"/>
    <limit effort="1" lower="-4.71238898038469" upper="4.71238898038469" velocity="0.497418"/>
    <dynamics damping="0" friction="0"/>
  </joint>
  <link name="cobotta_pro_J5">
    <visual>
      <origin rpy="0 0 0" xyz="0 0 0"/>
      <geometry>
        <mesh filename="package://denso_robot_descriptions/robots/cvrb0609/meshes/J5.dae" scale="1 1 1"/>
      </geometry>
    </visual>
    <collision>
      <origin rpy="0 0 0" xyz="0 0 0"/>
      <geometry>
        <mesh filename="package://denso_robot_descriptions/robots/cvrb0609/meshes/J5.dae" scale="1 1 1"/>
      </geometry>
    </collision>
    <inertial>
      <mass value="1"/>
      <origin rpy="0.000000 0.000000 0.000000" xyz="0.000000 0.000000 0.000000"/>
      <inertia ixx="1" ixy="0" ixz="0" iyy="1" iyz="0" izz="1"/>
    </inertial>
  </link>
  <joint name="cobotta_pro_joint_5" type="revolute">
    <parent link="cobotta_pro_J4"/>
    <child link="cobotta_pro_J5"/>
    <origin rpy="0.000000 0.000000 0.000000" xyz="0.000000 0.030000 0.088000"/>
    <axis xyz="-0.000000 1.000000 -0.000000"/>
    <limit effort="1" lower="-2.61799387799149" upper="2.61799387799149" velocity="0.497418"/>
    <dynamics damping="0" friction="0"/>
  </joint>
  <link name="cobotta_pro_J6">
    <visual>
      <origin rpy="0 0 0" xyz="0 0 0"/>
      <geometry>
        <mesh filename="package://denso_robot_descriptions/robots/cvrb0609/meshes/J6.dae" scale="1 1 1"/>
      </geometry>
    </visual>
    <collision>
      <origin rpy="0 0 0" xyz="0 0 0"/>
      <geometry>
        <mesh filename="package://denso_robot_descriptions/robots/cvrb0609/meshes/J6.dae" scale="1 1 1"/>
      </geometry>
    </collision>
    <inertial>
      <mass value="1"/>
      <origin rpy="0.000000 0.000000 0.000000" xyz="0.000000 0.000000 0.000000"/>
      <inertia ixx="1" ixy="0" ixz="0" iyy="1" iyz="0" izz="1"/>
    </inertial>
  </link>
  <joint name="cobotta_pro_joint_6" type="revolute">
    <parent link="cobotta_pro_J5"/>
    <child link="cobotta_pro_J6"/>
    <origin rpy="0.000000 0.000000 0.000000" xyz="0.000000 0.120000 0.160000"/>
    <axis xyz="-0.000000 -0.000000 1.000000"/>
    <limit effort="1" lower="-6.28318530717959" upper="6.28318530717959" velocity="0.596903"/>
    <dynamics damping="0" friction="0"/>
  </joint>
  <ros2_control name="cobotta_pro_TopicBasedSystem" type="system">
      <hardware>
        <plugin>topic_based_ros2_control/TopicBasedSystem</plugin>
        <param name="joint_commands_topic">/topic_based_joint_commands</param>
        <param name="joint_states_topic">/topic_based_joint_states</param>
      </hardware>
    <joint name="cobotta_pro_joint_1">
      <command_interface name="position">
        <param name="min">-4.712389</param>
        <param name="max">4.712389</param>
      </command_interface>
      <state_interface name="position"/>
      <state_interface name="velocity"/>
    </joint>
    <joint name="cobotta_pro_joint_2">
      <command_interface name="position">
        <param name="min">-2.617994</param>
        <param name="max">2.617994</param>
      </command_interface>
      <state_interface name="position"/>
      <state_interface name="velocity"/>
    </joint>
    <joint name="cobotta_pro_joint_3">
      <command_interface name="position">
        <param name="min">-2.617994</param>
        <param name="max">2.617994</param>
      </command_interface>
      <state_interface name="position"/>
      <state_interface name="velocity"/>
    </joint>
    <joint name="cobotta_pro_joint_4">
      <command_interface name="position">
        <param name="min">-4.712389</param>
        <param name="max">4.712389</param>
      </command_interface>
      <state_interface name="position"/>
      <state_interface name="velocity"/>
    </joint>
    <joint name="cobotta_pro_joint_5">
      <command_interface name="position">
        <param name="min">-2.617994</param>
        <param name="max">2.617994</param>
      </command_interface>
      <state_interface name="position"/>
      <state_interface name="velocity"/>
    </joint>
    <joint name="cobotta_pro_joint_6">
      <command_interface name="position">
        <param name="min">-6.283185</param>
        <param name="max">6.283185</param>
      </command_interface>
      <state_interface name="position"/>
      <state_interface name="velocity"/>
    </joint>
  </ros2_control>
  <link name="world"/>
  <!-- base_plate link to cobotta link -->
  <joint name="joint_w" type="fixed">
    <origin rpy="0 0 1.5708" xyz="0 0 0"/>
    <parent link="robot_base_plate_link"/>
    <child link="cobotta_pro_base_link"/>
  </joint>
  <joint name="world_cell_joint" type="fixed">
    <parent link="world"/>
    <child link="cell_link"/>
    <origin rpy="0 0 0" xyz="0 0 0"/>
  </joint>
  <link name="cell_link">
    <inertial>
      <origin rpy="0 0 0" xyz="-0.010188 0.010903 0.93146"/>
      <mass value="1383.8"/>
      <inertia ixx="833.74" ixy="-0.082289" ixz="0.013641" iyy="819.21" iyz="0.033946" izz="522.69"/>
    </inertial>
    <visual>
      <origin rpy="0 0 0" xyz="0 0 0"/>
      <geometry>
        <mesh filename="package://techtory_cell_description/urdf/mesh/cell_link.STL"/>
      </geometry>
      <material name="">
        <color rgba="0.85098 0.72157 0.72157 1"/>
      </material>
    </visual>
    <collision>
      <origin rpy="0 0 0" xyz="0 0 0"/>
      <geometry>
        <mesh filename="package://techtory_cell_description/urdf/mesh/cell_link.STL"/>
      </geometry>
    </collision>
  </link>
  <link name="robot_base_plate_link">
    <inertial>
      <origin rpy="0 0 0" xyz="-0.010188 0.010903 0.93146"/>
      <mass value="1383.8"/>
      <inertia ixx="833.74" ixy="-0.082289" ixz="0.013641" iyy="819.21" iyz="0.033946" izz="522.69"/>
    </inertial>
    <visual>
      <origin rpy="0 0 0" xyz="0 0 0"/>
      <geometry>
        <mesh filename="package://techtory_cell_description/urdf/mesh/robot_base_link.STL" scale="0.9 0.9 1.5"/>
      </geometry>
      <material name="">
        <color rgba="0.85098 0.72157 0.72157 1"/>
      </material>
    </visual>
    <collision>
      <origin rpy="0 0 0" xyz="0 0 0"/>
      <geometry>
        <mesh filename="package://techtory_cell_description/urdf/mesh/robot_base_link.STL" scale="0.9 0.9 1.5"/>
      </geometry>
    </collision>
  </link>
  <joint name="robot_base_plate_link_joint" type="fixed">
    <parent link="cell_link"/>
    <child link="robot_base_plate_link"/>
    <origin rpy="0 0 0" xyz="0 -0.3 0.93"/>
  </joint>
</robot>
